index
index
Internal Server Error: /
Traceback (most recent call last):
  File "/Library/Frameworks/Python.framework/Versions/3.3/lib/python3.3/site-packages/django/core/handlers/base.py", line 115, in get_response
    response = callback(request, *callback_args, **callback_kwargs)
TypeError: __init__() takes 1 positional argument but 2 were given
Internal Server Error: /
Traceback (most recent call last):
  File "/Library/Frameworks/Python.framework/Versions/3.3/lib/python3.3/site-packages/django/core/handlers/base.py", line 115, in get_response
    response = callback(request, *callback_args, **callback_kwargs)
TypeError: __init__() takes 1 positional argument but 2 were given
Internal Server Error: /
Traceback (most recent call last):
  File "/Library/Frameworks/Python.framework/Versions/3.3/lib/python3.3/site-packages/django/core/handlers/base.py", line 115, in get_response
    response = callback(request, *callback_args, **callback_kwargs)
TypeError: __init__() takes 1 positional argument but 2 were given
Internal Server Error: /
Traceback (most recent call last):
  File "/Library/Frameworks/Python.framework/Versions/3.3/lib/python3.3/site-packages/django/core/handlers/base.py", line 115, in get_response
    response = callback(request, *callback_args, **callback_kwargs)
TypeError: __init__() takes 1 positional argument but 2 were given
Forbidden (CSRF token missing or incorrect.): /register
Forbidden (CSRF token missing or incorrect.): /register
Internal Server Error: /register
Traceback (most recent call last):
  File "/Library/Frameworks/Python.framework/Versions/3.3/lib/python3.3/site-packages/django/core/handlers/base.py", line 133, in get_response
    raise ValueError("The view %s.%s didn't return an HttpResponse object." % (callback.__module__, view_name))
ValueError: The view bbs.views.RegisterView didn't return an HttpResponse object.
<QueryDict: {'password': ['root'], 'user_id': ['never'], 'email': ['never@213'], 'csrfmiddlewaretoken': ['3ODDJ38JEhXxfHheqaxzqHIriN9yJKUP']}>
Internal Server Error: /register
Traceback (most recent call last):
  File "/Library/Frameworks/Python.framework/Versions/3.3/lib/python3.3/site-packages/django/core/handlers/base.py", line 133, in get_response
    raise ValueError("The view %s.%s didn't return an HttpResponse object." % (callback.__module__, view_name))
ValueError: The view bbs.views.RegisterView didn't return an HttpResponse object.
<QueryDict: {'csrfmiddlewaretoken': ['3ODDJ38JEhXxfHheqaxzqHIriN9yJKUP'], 'password': ['root'], 'user_id': ['never'], 'email': ['never@213']}>
Internal Server Error: /register
Traceback (most recent call last):
  File "/Library/Frameworks/Python.framework/Versions/3.3/lib/python3.3/site-packages/django/core/handlers/base.py", line 133, in get_response
    raise ValueError("The view %s.%s didn't return an HttpResponse object." % (callback.__module__, view_name))
ValueError: The view bbs.views.RegisterView didn't return an HttpResponse object.
<QueryDict: {'user_id': ['never'], 'email': ['never@213'], 'csrfmiddlewaretoken': ['3ODDJ38JEhXxfHheqaxzqHIriN9yJKUP'], 'password': ['root']}>
Internal Server Error: /register
Traceback (most recent call last):
  File "/Library/Frameworks/Python.framework/Versions/3.3/lib/python3.3/site-packages/django/core/handlers/base.py", line 133, in get_response
    raise ValueError("The view %s.%s didn't return an HttpResponse object." % (callback.__module__, view_name))
ValueError: The view bbs.views.RegisterView didn't return an HttpResponse object.
<QueryDict: {'password': ['root'], 'user_id': ['never'], 'email': ['never@213'], 'csrfmiddlewaretoken': ['3ODDJ38JEhXxfHheqaxzqHIriN9yJKUP']}>
<QueryDict: {'csrfmiddlewaretoken': ['3ODDJ38JEhXxfHheqaxzqHIriN9yJKUP'], 'password': ['123'], 'user_id': ['123'], 'email': ['never@nwdw']}>
Forbidden (CSRF token missing or incorrect.): /login
Forbidden (CSRF token missing or incorrect.): /login
Internal Server Error: /login
Traceback (most recent call last):
  File "/Library/Frameworks/Python.framework/Versions/3.3/lib/python3.3/site-packages/django/core/handlers/base.py", line 133, in get_response
    raise ValueError("The view %s.%s didn't return an HttpResponse object." % (callback.__module__, view_name))
ValueError: The view bbs.views.LoginView didn't return an HttpResponse object.
Internal Server Error: /
Traceback (most recent call last):
  File "/Library/Frameworks/Python.framework/Versions/3.3/lib/python3.3/site-packages/django/contrib/sessions/backends/base.py", line 162, in _get_session
    return self._session_cache
AttributeError: 'SessionStore' object has no attribute '_session_cache'

During handling of the above exception, another exception occurred:

Traceback (most recent call last):
  File "/Library/Frameworks/Python.framework/Versions/3.3/lib/python3.3/site-packages/django/core/handlers/base.py", line 115, in get_response
    response = callback(request, *callback_args, **callback_kwargs)
  File "/Library/Frameworks/Python.framework/Versions/3.3/lib/python3.3/site-packages/django/views/generic/base.py", line 68, in view
    return self.dispatch(request, *args, **kwargs)
  File "/Library/Frameworks/Python.framework/Versions/3.3/lib/python3.3/site-packages/django/views/generic/base.py", line 86, in dispatch
    return handler(request, *args, **kwargs)
  File "/Users/never/PycharmProjects/bbs/bbs/views.py", line 12, in get
    if request.user.is_authenticated():
  File "/Library/Frameworks/Python.framework/Versions/3.3/lib/python3.3/site-packages/django/utils/functional.py", line 204, in inner
    self._setup()
  File "/Library/Frameworks/Python.framework/Versions/3.3/lib/python3.3/site-packages/django/utils/functional.py", line 270, in _setup
    self._wrapped = self._setupfunc()
  File "/Library/Frameworks/Python.framework/Versions/3.3/lib/python3.3/site-packages/django/contrib/auth/middleware.py", line 18, in <lambda>
    request.user = SimpleLazyObject(lambda: get_user(request))
  File "/Library/Frameworks/Python.framework/Versions/3.3/lib/python3.3/site-packages/django/contrib/auth/middleware.py", line 10, in get_user
    request._cached_user = auth.get_user(request)
  File "/Library/Frameworks/Python.framework/Versions/3.3/lib/python3.3/site-packages/django/contrib/auth/__init__.py", line 136, in get_user
    user_id = request.session[SESSION_KEY]
  File "/Library/Frameworks/Python.framework/Versions/3.3/lib/python3.3/site-packages/django/contrib/sessions/backends/base.py", line 44, in __getitem__
    return self._session[key]
  File "/Library/Frameworks/Python.framework/Versions/3.3/lib/python3.3/site-packages/django/contrib/sessions/backends/base.py", line 167, in _get_session
    self._session_cache = self.load()
  File "/Library/Frameworks/Python.framework/Versions/3.3/lib/python3.3/site-packages/django/contrib/sessions/backends/db.py", line 18, in load
    expire_date__gt=timezone.now()
  File "/Library/Frameworks/Python.framework/Versions/3.3/lib/python3.3/site-packages/django/db/models/manager.py", line 143, in get
    return self.get_query_set().get(*args, **kwargs)
  File "/Library/Frameworks/Python.framework/Versions/3.3/lib/python3.3/site-packages/django/db/models/query.py", line 398, in get
    num = len(clone)
  File "/Library/Frameworks/Python.framework/Versions/3.3/lib/python3.3/site-packages/django/db/models/query.py", line 106, in __len__
    self._result_cache = list(self.iterator())
  File "/Library/Frameworks/Python.framework/Versions/3.3/lib/python3.3/site-packages/django/db/models/query.py", line 317, in iterator
    for row in compiler.results_iter():
  File "/Library/Frameworks/Python.framework/Versions/3.3/lib/python3.3/site-packages/django/db/models/sql/compiler.py", line 775, in results_iter
    for rows in self.execute_sql(MULTI):
  File "/Library/Frameworks/Python.framework/Versions/3.3/lib/python3.3/site-packages/django/db/models/sql/compiler.py", line 845, in execute_sql
    cursor = self.connection.cursor()
  File "/Library/Frameworks/Python.framework/Versions/3.3/lib/python3.3/site-packages/django/db/backends/__init__.py", line 324, in cursor
    cursor = self.make_debug_cursor(self._cursor())
  File "/Library/Frameworks/Python.framework/Versions/3.3/lib/python3.3/site-packages/django/db/backends/mysql/base.py", line 406, in _cursor
    self.connection = Database.connect(**kwargs)
  File "/Library/Frameworks/Python.framework/Versions/3.3/lib/python3.3/site-packages/MySQL_python-1.2.3-py3.3-macosx-10.6-intel.egg/MySQLdb/__init__.py", line 81, in Connect
    return Connection(*args, **kwargs)
  File "/Library/Frameworks/Python.framework/Versions/3.3/lib/python3.3/site-packages/MySQL_python-1.2.3-py3.3-macosx-10.6-intel.egg/MySQLdb/connections.py", line 175, in __init__
    super(Connection, self).__init__(*args, **kwargs2)
_mysql_exceptions.OperationalError: (2003, "Can't connect to MySQL server on '127.0.0.1' (61)")
Internal Server Error: /posts/
Traceback (most recent call last):
  File "/Library/Frameworks/Python.framework/Versions/3.3/lib/python3.3/site-packages/django/core/handlers/base.py", line 140, in get_response
    response = response.render()
  File "/Library/Frameworks/Python.framework/Versions/3.3/lib/python3.3/site-packages/django/template/response.py", line 105, in render
    self.content = self.rendered_content
  File "/Library/Frameworks/Python.framework/Versions/3.3/lib/python3.3/site-packages/django/template/response.py", line 80, in rendered_content
    template = self.resolve_template(self.template_name)
  File "/Library/Frameworks/Python.framework/Versions/3.3/lib/python3.3/site-packages/django/template/response.py", line 56, in resolve_template
    return loader.select_template(template)
  File "/Library/Frameworks/Python.framework/Versions/3.3/lib/python3.3/site-packages/django/template/loader.py", line 194, in select_template
    raise TemplateDoesNotExist(', '.join(not_found))
django.template.base.TemplateDoesNotExist: templates/index.html, posts/post_list.html
Internal Server Error: /posts/
Traceback (most recent call last):
  File "/Library/Frameworks/Python.framework/Versions/3.3/lib/python3.3/site-packages/django/core/handlers/base.py", line 140, in get_response
    response = response.render()
  File "/Library/Frameworks/Python.framework/Versions/3.3/lib/python3.3/site-packages/django/template/response.py", line 105, in render
    self.content = self.rendered_content
  File "/Library/Frameworks/Python.framework/Versions/3.3/lib/python3.3/site-packages/django/template/response.py", line 80, in rendered_content
    template = self.resolve_template(self.template_name)
  File "/Library/Frameworks/Python.framework/Versions/3.3/lib/python3.3/site-packages/django/template/response.py", line 56, in resolve_template
    return loader.select_template(template)
  File "/Library/Frameworks/Python.framework/Versions/3.3/lib/python3.3/site-packages/django/template/loader.py", line 194, in select_template
    raise TemplateDoesNotExist(', '.join(not_found))
django.template.base.TemplateDoesNotExist: templates/index.html, posts/post_list.html
Internal Server Error: /login
Traceback (most recent call last):
  File "/Library/Frameworks/Python.framework/Versions/3.3/lib/python3.3/site-packages/django/core/handlers/base.py", line 133, in get_response
    raise ValueError("The view %s.%s didn't return an HttpResponse object." % (callback.__module__, view_name))
ValueError: The view bbs.views.LoginView didn't return an HttpResponse object.
<QueryDict: {'email': ['123@123.123'], 'user_id': ['never'], 'password': ['123'], 'csrfmiddlewaretoken': ['vzcQa9UFTXowsKPlmhuUleqDxKBgyCRQ']}>
Internal Server Error: /register
Traceback (most recent call last):
  File "/Library/Frameworks/Python.framework/Versions/3.3/lib/python3.3/site-packages/django/db/backends/mysql/base.py", line 120, in execute
    return self.cursor.execute(query, args)
  File "/Library/Frameworks/Python.framework/Versions/3.3/lib/python3.3/site-packages/MySQL_python-1.2.3-py3.3-macosx-10.6-intel.egg/MySQLdb/cursors.py", line 185, in execute
    self.errorhandler(self, exc, value)
  File "/Library/Frameworks/Python.framework/Versions/3.3/lib/python3.3/site-packages/MySQL_python-1.2.3-py3.3-macosx-10.6-intel.egg/MySQLdb/connections.py", line 37, in defaulterrorhandler
    raise errorvalue
  File "/Library/Frameworks/Python.framework/Versions/3.3/lib/python3.3/site-packages/MySQL_python-1.2.3-py3.3-macosx-10.6-intel.egg/MySQLdb/cursors.py", line 172, in execute
    r = self._query(query)
  File "/Library/Frameworks/Python.framework/Versions/3.3/lib/python3.3/site-packages/MySQL_python-1.2.3-py3.3-macosx-10.6-intel.egg/MySQLdb/cursors.py", line 332, in _query
    rowcount = self._do_query(q)
  File "/Library/Frameworks/Python.framework/Versions/3.3/lib/python3.3/site-packages/MySQL_python-1.2.3-py3.3-macosx-10.6-intel.egg/MySQLdb/cursors.py", line 296, in _do_query
    db.query(q)
_mysql_exceptions.IntegrityError: (1062, "Duplicate entry 'never' for key 'username'")

During handling of the above exception, another exception occurred:

Traceback (most recent call last):
  File "/Library/Frameworks/Python.framework/Versions/3.3/lib/python3.3/site-packages/django/core/handlers/base.py", line 115, in get_response
    response = callback(request, *callback_args, **callback_kwargs)
  File "/Library/Frameworks/Python.framework/Versions/3.3/lib/python3.3/site-packages/django/views/generic/base.py", line 68, in view
    return self.dispatch(request, *args, **kwargs)
  File "/Library/Frameworks/Python.framework/Versions/3.3/lib/python3.3/site-packages/django/views/generic/base.py", line 86, in dispatch
    return handler(request, *args, **kwargs)
  File "/Users/never/PycharmProjects/bbs/bbs/views.py", line 39, in post
    user = User.objects.create_user(request.POST['user_id'], request.POST['email'], request.POST['password'])
  File "/Library/Frameworks/Python.framework/Versions/3.3/lib/python3.3/site-packages/django/contrib/auth/models.py", line 186, in create_user
    user.save(using=self._db)
  File "/Library/Frameworks/Python.framework/Versions/3.3/lib/python3.3/site-packages/django/db/models/base.py", line 546, in save
    force_update=force_update, update_fields=update_fields)
  File "/Library/Frameworks/Python.framework/Versions/3.3/lib/python3.3/site-packages/django/db/models/base.py", line 650, in save_base
    result = manager._insert([self], fields=fields, return_id=update_pk, using=using, raw=raw)
  File "/Library/Frameworks/Python.framework/Versions/3.3/lib/python3.3/site-packages/django/db/models/manager.py", line 215, in _insert
    return insert_query(self.model, objs, fields, **kwargs)
  File "/Library/Frameworks/Python.framework/Versions/3.3/lib/python3.3/site-packages/django/db/models/query.py", line 1675, in insert_query
    return query.get_compiler(using=using).execute_sql(return_id)
  File "/Library/Frameworks/Python.framework/Versions/3.3/lib/python3.3/site-packages/django/db/models/sql/compiler.py", line 943, in execute_sql
    cursor.execute(sql, params)
  File "/Library/Frameworks/Python.framework/Versions/3.3/lib/python3.3/site-packages/django/db/backends/util.py", line 41, in execute
    return self.cursor.execute(sql, params)
  File "/Library/Frameworks/Python.framework/Versions/3.3/lib/python3.3/site-packages/django/db/backends/mysql/base.py", line 122, in execute
    six.reraise(utils.IntegrityError, utils.IntegrityError(*tuple(e.args)), sys.exc_info()[2])
  File "/Library/Frameworks/Python.framework/Versions/3.3/lib/python3.3/site-packages/django/utils/six.py", line 490, in reraise
    raise value.with_traceback(tb)
  File "/Library/Frameworks/Python.framework/Versions/3.3/lib/python3.3/site-packages/django/db/backends/mysql/base.py", line 120, in execute
    return self.cursor.execute(query, args)
  File "/Library/Frameworks/Python.framework/Versions/3.3/lib/python3.3/site-packages/MySQL_python-1.2.3-py3.3-macosx-10.6-intel.egg/MySQLdb/cursors.py", line 185, in execute
    self.errorhandler(self, exc, value)
  File "/Library/Frameworks/Python.framework/Versions/3.3/lib/python3.3/site-packages/MySQL_python-1.2.3-py3.3-macosx-10.6-intel.egg/MySQLdb/connections.py", line 37, in defaulterrorhandler
    raise errorvalue
  File "/Library/Frameworks/Python.framework/Versions/3.3/lib/python3.3/site-packages/MySQL_python-1.2.3-py3.3-macosx-10.6-intel.egg/MySQLdb/cursors.py", line 172, in execute
    r = self._query(query)
  File "/Library/Frameworks/Python.framework/Versions/3.3/lib/python3.3/site-packages/MySQL_python-1.2.3-py3.3-macosx-10.6-intel.egg/MySQLdb/cursors.py", line 332, in _query
    rowcount = self._do_query(q)
  File "/Library/Frameworks/Python.framework/Versions/3.3/lib/python3.3/site-packages/MySQL_python-1.2.3-py3.3-macosx-10.6-intel.egg/MySQLdb/cursors.py", line 296, in _do_query
    db.query(q)
django.db.utils.IntegrityError: (1062, "Duplicate entry 'never' for key 'username'")
<QueryDict: {'csrfmiddlewaretoken': ['vzcQa9UFTXowsKPlmhuUleqDxKBgyCRQ'], 'password': ['123'], 'user_id': ['never'], 'email': ['123@123.123']}>
Internal Server Error: /posts
Traceback (most recent call last):
  File "/Library/Frameworks/Python.framework/Versions/3.3/lib/python3.3/site-packages/django/template/base.py", line 270, in parse
    compile_func = self.tags[command]
KeyError: 'end'

During handling of the above exception, another exception occurred:

Traceback (most recent call last):
  File "/Library/Frameworks/Python.framework/Versions/3.3/lib/python3.3/site-packages/django/core/handlers/base.py", line 140, in get_response
    response = response.render()
  File "/Library/Frameworks/Python.framework/Versions/3.3/lib/python3.3/site-packages/django/template/response.py", line 105, in render
    self.content = self.rendered_content
  File "/Library/Frameworks/Python.framework/Versions/3.3/lib/python3.3/site-packages/django/template/response.py", line 80, in rendered_content
    template = self.resolve_template(self.template_name)
  File "/Library/Frameworks/Python.framework/Versions/3.3/lib/python3.3/site-packages/django/template/response.py", line 56, in resolve_template
    return loader.select_template(template)
  File "/Library/Frameworks/Python.framework/Versions/3.3/lib/python3.3/site-packages/django/template/loader.py", line 188, in select_template
    return get_template(template_name)
  File "/Library/Frameworks/Python.framework/Versions/3.3/lib/python3.3/site-packages/django/template/loader.py", line 146, in get_template
    template, origin = find_template(template_name)
  File "/Library/Frameworks/Python.framework/Versions/3.3/lib/python3.3/site-packages/django/template/loader.py", line 135, in find_template
    source, display_name = loader(name, dirs)
  File "/Library/Frameworks/Python.framework/Versions/3.3/lib/python3.3/site-packages/django/template/loader.py", line 43, in __call__
    return self.load_template(template_name, template_dirs)
  File "/Library/Frameworks/Python.framework/Versions/3.3/lib/python3.3/site-packages/django/template/loader.py", line 49, in load_template
    template = get_template_from_string(source, origin, template_name)
  File "/Library/Frameworks/Python.framework/Versions/3.3/lib/python3.3/site-packages/django/template/loader.py", line 157, in get_template_from_string
    return Template(source, origin, name)
  File "/Library/Frameworks/Python.framework/Versions/3.3/lib/python3.3/site-packages/django/template/base.py", line 125, in __init__
    self.nodelist = compile_string(template_string, origin)
  File "/Library/Frameworks/Python.framework/Versions/3.3/lib/python3.3/site-packages/django/template/base.py", line 153, in compile_string
    return parser.parse()
  File "/Library/Frameworks/Python.framework/Versions/3.3/lib/python3.3/site-packages/django/template/base.py", line 274, in parse
    compiled_result = compile_func(self, token)
  File "/Library/Frameworks/Python.framework/Versions/3.3/lib/python3.3/site-packages/django/template/loader_tags.py", line 215, in do_extends
    nodelist = parser.parse()
  File "/Library/Frameworks/Python.framework/Versions/3.3/lib/python3.3/site-packages/django/template/base.py", line 274, in parse
    compiled_result = compile_func(self, token)
  File "/Library/Frameworks/Python.framework/Versions/3.3/lib/python3.3/site-packages/django/template/loader_tags.py", line 190, in do_block
    nodelist = parser.parse(('endblock',))
  File "/Library/Frameworks/Python.framework/Versions/3.3/lib/python3.3/site-packages/django/template/base.py", line 272, in parse
    self.invalid_block_tag(token, command, parse_until)
  File "/Library/Frameworks/Python.framework/Versions/3.3/lib/python3.3/site-packages/django/template/base.py", line 327, in invalid_block_tag
    (command, get_text_list(["'%s'" % p for p in parse_until])))
django.template.base.TemplateSyntaxError: Invalid block tag: 'end', expected 'endblock'
Internal Server Error: /posts
Traceback (most recent call last):
  File "/Library/Frameworks/Python.framework/Versions/3.3/lib/python3.3/site-packages/django/core/handlers/base.py", line 140, in get_response
    response = response.render()
  File "/Library/Frameworks/Python.framework/Versions/3.3/lib/python3.3/site-packages/django/template/response.py", line 105, in render
    self.content = self.rendered_content
  File "/Library/Frameworks/Python.framework/Versions/3.3/lib/python3.3/site-packages/django/template/response.py", line 80, in rendered_content
    template = self.resolve_template(self.template_name)
  File "/Library/Frameworks/Python.framework/Versions/3.3/lib/python3.3/site-packages/django/template/response.py", line 56, in resolve_template
    return loader.select_template(template)
  File "/Library/Frameworks/Python.framework/Versions/3.3/lib/python3.3/site-packages/django/template/loader.py", line 188, in select_template
    return get_template(template_name)
  File "/Library/Frameworks/Python.framework/Versions/3.3/lib/python3.3/site-packages/django/template/loader.py", line 146, in get_template
    template, origin = find_template(template_name)
  File "/Library/Frameworks/Python.framework/Versions/3.3/lib/python3.3/site-packages/django/template/loader.py", line 135, in find_template
    source, display_name = loader(name, dirs)
  File "/Library/Frameworks/Python.framework/Versions/3.3/lib/python3.3/site-packages/django/template/loader.py", line 43, in __call__
    return self.load_template(template_name, template_dirs)
  File "/Library/Frameworks/Python.framework/Versions/3.3/lib/python3.3/site-packages/django/template/loader.py", line 49, in load_template
    template = get_template_from_string(source, origin, template_name)
  File "/Library/Frameworks/Python.framework/Versions/3.3/lib/python3.3/site-packages/django/template/loader.py", line 157, in get_template_from_string
    return Template(source, origin, name)
  File "/Library/Frameworks/Python.framework/Versions/3.3/lib/python3.3/site-packages/django/template/base.py", line 125, in __init__
    self.nodelist = compile_string(template_string, origin)
  File "/Library/Frameworks/Python.framework/Versions/3.3/lib/python3.3/site-packages/django/template/base.py", line 153, in compile_string
    return parser.parse()
  File "/Library/Frameworks/Python.framework/Versions/3.3/lib/python3.3/site-packages/django/template/base.py", line 274, in parse
    compiled_result = compile_func(self, token)
  File "/Library/Frameworks/Python.framework/Versions/3.3/lib/python3.3/site-packages/django/template/loader_tags.py", line 215, in do_extends
    nodelist = parser.parse()
  File "/Library/Frameworks/Python.framework/Versions/3.3/lib/python3.3/site-packages/django/template/base.py", line 274, in parse
    compiled_result = compile_func(self, token)
  File "/Library/Frameworks/Python.framework/Versions/3.3/lib/python3.3/site-packages/django/template/loader_tags.py", line 190, in do_block
    nodelist = parser.parse(('endblock',))
  File "/Library/Frameworks/Python.framework/Versions/3.3/lib/python3.3/site-packages/django/template/base.py", line 274, in parse
    compiled_result = compile_func(self, token)
  File "/Library/Frameworks/Python.framework/Versions/3.3/lib/python3.3/site-packages/django/template/defaulttags.py", line 769, in do_for
    nodelist_loop = parser.parse(('empty', 'endfor',))
  File "/Library/Frameworks/Python.framework/Versions/3.3/lib/python3.3/site-packages/django/template/base.py", line 253, in parse
    filter_expression = self.compile_filter(token.contents)
  File "/Library/Frameworks/Python.framework/Versions/3.3/lib/python3.3/site-packages/django/template/base.py", line 353, in compile_filter
    return FilterExpression(token, self)
  File "/Library/Frameworks/Python.framework/Versions/3.3/lib/python3.3/site-packages/django/template/base.py", line 570, in __init__
    "from '%s'" % (token[upto:], token))
django.template.base.TemplateSyntaxError: Could not parse the remainder: '['id']' from 'post['id']'
Internal Server Error: /posts
Traceback (most recent call last):
  File "/Library/Frameworks/Python.framework/Versions/3.3/lib/python3.3/site-packages/django/template/base.py", line 270, in parse
    compile_func = self.tags[command]
KeyError: 'end'

During handling of the above exception, another exception occurred:

Traceback (most recent call last):
  File "/Library/Frameworks/Python.framework/Versions/3.3/lib/python3.3/site-packages/django/core/handlers/base.py", line 140, in get_response
    response = response.render()
  File "/Library/Frameworks/Python.framework/Versions/3.3/lib/python3.3/site-packages/django/template/response.py", line 105, in render
    self.content = self.rendered_content
  File "/Library/Frameworks/Python.framework/Versions/3.3/lib/python3.3/site-packages/django/template/response.py", line 80, in rendered_content
    template = self.resolve_template(self.template_name)
  File "/Library/Frameworks/Python.framework/Versions/3.3/lib/python3.3/site-packages/django/template/response.py", line 56, in resolve_template
    return loader.select_template(template)
  File "/Library/Frameworks/Python.framework/Versions/3.3/lib/python3.3/site-packages/django/template/loader.py", line 188, in select_template
    return get_template(template_name)
  File "/Library/Frameworks/Python.framework/Versions/3.3/lib/python3.3/site-packages/django/template/loader.py", line 146, in get_template
    template, origin = find_template(template_name)
  File "/Library/Frameworks/Python.framework/Versions/3.3/lib/python3.3/site-packages/django/template/loader.py", line 135, in find_template
    source, display_name = loader(name, dirs)
  File "/Library/Frameworks/Python.framework/Versions/3.3/lib/python3.3/site-packages/django/template/loader.py", line 43, in __call__
    return self.load_template(template_name, template_dirs)
  File "/Library/Frameworks/Python.framework/Versions/3.3/lib/python3.3/site-packages/django/template/loader.py", line 49, in load_template
    template = get_template_from_string(source, origin, template_name)
  File "/Library/Frameworks/Python.framework/Versions/3.3/lib/python3.3/site-packages/django/template/loader.py", line 157, in get_template_from_string
    return Template(source, origin, name)
  File "/Library/Frameworks/Python.framework/Versions/3.3/lib/python3.3/site-packages/django/template/base.py", line 125, in __init__
    self.nodelist = compile_string(template_string, origin)
  File "/Library/Frameworks/Python.framework/Versions/3.3/lib/python3.3/site-packages/django/template/base.py", line 153, in compile_string
    return parser.parse()
  File "/Library/Frameworks/Python.framework/Versions/3.3/lib/python3.3/site-packages/django/template/base.py", line 274, in parse
    compiled_result = compile_func(self, token)
  File "/Library/Frameworks/Python.framework/Versions/3.3/lib/python3.3/site-packages/django/template/loader_tags.py", line 215, in do_extends
    nodelist = parser.parse()
  File "/Library/Frameworks/Python.framework/Versions/3.3/lib/python3.3/site-packages/django/template/base.py", line 274, in parse
    compiled_result = compile_func(self, token)
  File "/Library/Frameworks/Python.framework/Versions/3.3/lib/python3.3/site-packages/django/template/loader_tags.py", line 190, in do_block
    nodelist = parser.parse(('endblock',))
  File "/Library/Frameworks/Python.framework/Versions/3.3/lib/python3.3/site-packages/django/template/base.py", line 274, in parse
    compiled_result = compile_func(self, token)
  File "/Library/Frameworks/Python.framework/Versions/3.3/lib/python3.3/site-packages/django/template/defaulttags.py", line 769, in do_for
    nodelist_loop = parser.parse(('empty', 'endfor',))
  File "/Library/Frameworks/Python.framework/Versions/3.3/lib/python3.3/site-packages/django/template/base.py", line 272, in parse
    self.invalid_block_tag(token, command, parse_until)
  File "/Library/Frameworks/Python.framework/Versions/3.3/lib/python3.3/site-packages/django/template/base.py", line 327, in invalid_block_tag
    (command, get_text_list(["'%s'" % p for p in parse_until])))
django.template.base.TemplateSyntaxError: Invalid block tag: 'end', expected 'empty' 或 'endfor'
Internal Server Error: /posts
Traceback (most recent call last):
  File "/Library/Frameworks/Python.framework/Versions/3.3/lib/python3.3/site-packages/django/db/models/options.py", line 349, in get_field_by_name
    return self._name_map[name]
AttributeError: 'Options' object has no attribute '_name_map'

During handling of the above exception, another exception occurred:

Traceback (most recent call last):
  File "/Library/Frameworks/Python.framework/Versions/3.3/lib/python3.3/site-packages/django/db/models/options.py", line 352, in get_field_by_name
    return cache[name]
KeyError: 'pub_date'

During handling of the above exception, another exception occurred:

Traceback (most recent call last):
  File "/Library/Frameworks/Python.framework/Versions/3.3/lib/python3.3/site-packages/django/db/models/sql/query.py", line 1325, in setup_joins
    field, model, direct, m2m = opts.get_field_by_name(name)
  File "/Library/Frameworks/Python.framework/Versions/3.3/lib/python3.3/site-packages/django/db/models/options.py", line 355, in get_field_by_name
    % (self.object_name, name))
django.db.models.fields.FieldDoesNotExist: Post has no field named 'pub_date'

During handling of the above exception, another exception occurred:

Traceback (most recent call last):
  File "/Library/Frameworks/Python.framework/Versions/3.3/lib/python3.3/site-packages/django/core/handlers/base.py", line 140, in get_response
    response = response.render()
  File "/Library/Frameworks/Python.framework/Versions/3.3/lib/python3.3/site-packages/django/template/response.py", line 105, in render
    self.content = self.rendered_content
  File "/Library/Frameworks/Python.framework/Versions/3.3/lib/python3.3/site-packages/django/template/response.py", line 82, in rendered_content
    content = template.render(context)
  File "/Library/Frameworks/Python.framework/Versions/3.3/lib/python3.3/site-packages/django/template/base.py", line 140, in render
    return self._render(context)
  File "/Library/Frameworks/Python.framework/Versions/3.3/lib/python3.3/site-packages/django/template/base.py", line 134, in _render
    return self.nodelist.render(context)
  File "/Library/Frameworks/Python.framework/Versions/3.3/lib/python3.3/site-packages/django/template/base.py", line 830, in render
    bit = self.render_node(node, context)
  File "/Library/Frameworks/Python.framework/Versions/3.3/lib/python3.3/site-packages/django/template/debug.py", line 74, in render_node
    return node.render(context)
  File "/Library/Frameworks/Python.framework/Versions/3.3/lib/python3.3/site-packages/django/template/loader_tags.py", line 124, in render
    return compiled_parent._render(context)
  File "/Library/Frameworks/Python.framework/Versions/3.3/lib/python3.3/site-packages/django/template/base.py", line 134, in _render
    return self.nodelist.render(context)
  File "/Library/Frameworks/Python.framework/Versions/3.3/lib/python3.3/site-packages/django/template/base.py", line 830, in render
    bit = self.render_node(node, context)
  File "/Library/Frameworks/Python.framework/Versions/3.3/lib/python3.3/site-packages/django/template/debug.py", line 74, in render_node
    return node.render(context)
  File "/Library/Frameworks/Python.framework/Versions/3.3/lib/python3.3/site-packages/django/template/loader_tags.py", line 63, in render
    result = block.nodelist.render(context)
  File "/Library/Frameworks/Python.framework/Versions/3.3/lib/python3.3/site-packages/django/template/base.py", line 830, in render
    bit = self.render_node(node, context)
  File "/Library/Frameworks/Python.framework/Versions/3.3/lib/python3.3/site-packages/django/template/debug.py", line 74, in render_node
    return node.render(context)
  File "/Library/Frameworks/Python.framework/Versions/3.3/lib/python3.3/site-packages/django/template/defaulttags.py", line 149, in render
    len_values = len(values)
  File "/Library/Frameworks/Python.framework/Versions/3.3/lib/python3.3/site-packages/django/db/models/query.py", line 106, in __len__
    self._result_cache = list(self.iterator())
  File "/Library/Frameworks/Python.framework/Versions/3.3/lib/python3.3/site-packages/django/db/models/query.py", line 317, in iterator
    for row in compiler.results_iter():
  File "/Library/Frameworks/Python.framework/Versions/3.3/lib/python3.3/site-packages/django/db/models/sql/compiler.py", line 775, in results_iter
    for rows in self.execute_sql(MULTI):
  File "/Library/Frameworks/Python.framework/Versions/3.3/lib/python3.3/site-packages/django/db/models/sql/compiler.py", line 836, in execute_sql
    sql, params = self.as_sql()
  File "/Library/Frameworks/Python.framework/Versions/3.3/lib/python3.3/site-packages/django/db/models/sql/compiler.py", line 75, in as_sql
    ordering, ordering_group_by = self.get_ordering()
  File "/Library/Frameworks/Python.framework/Versions/3.3/lib/python3.3/site-packages/django/db/models/sql/compiler.py", line 394, in get_ordering
    self.query.model._meta, default_order=asc):
  File "/Library/Frameworks/Python.framework/Versions/3.3/lib/python3.3/site-packages/django/db/models/sql/compiler.py", line 420, in find_ordering_name
    field, col, alias, joins, opts = self._setup_joins(pieces, opts, alias)
  File "/Library/Frameworks/Python.framework/Versions/3.3/lib/python3.3/site-packages/django/db/models/sql/compiler.py", line 453, in _setup_joins
    opts, alias, False)
  File "/Library/Frameworks/Python.framework/Versions/3.3/lib/python3.3/site-packages/django/db/models/sql/query.py", line 1337, in setup_joins
    "Choices are: %s" % (name, ", ".join(names)))
django.core.exceptions.FieldError: Cannot resolve keyword 'pub_date' into field. Choices are: author, content, id, post_date, reply, title
Internal Server Error: /posts
Traceback (most recent call last):
  File "/Library/Frameworks/Python.framework/Versions/3.3/lib/python3.3/site-packages/django/template/defaulttags.py", line 420, in render
    current_app=context.current_app)
  File "/Library/Frameworks/Python.framework/Versions/3.3/lib/python3.3/site-packages/django/core/urlresolvers.py", line 496, in reverse
    return iri_to_uri(resolver._reverse_with_prefix(view, prefix, *args, **kwargs))
  File "/Library/Frameworks/Python.framework/Versions/3.3/lib/python3.3/site-packages/django/core/urlresolvers.py", line 416, in _reverse_with_prefix
    "arguments '%s' not found." % (lookup_view_s, args, kwargs))
django.core.urlresolvers.NoReverseMatch: Reverse for 'bbs.detail' with arguments '(1,)' and keyword arguments '{}' not found.

During handling of the above exception, another exception occurred:

Traceback (most recent call last):
  File "/Library/Frameworks/Python.framework/Versions/3.3/lib/python3.3/site-packages/django/core/handlers/base.py", line 140, in get_response
    response = response.render()
  File "/Library/Frameworks/Python.framework/Versions/3.3/lib/python3.3/site-packages/django/template/response.py", line 105, in render
    self.content = self.rendered_content
  File "/Library/Frameworks/Python.framework/Versions/3.3/lib/python3.3/site-packages/django/template/response.py", line 82, in rendered_content
    content = template.render(context)
  File "/Library/Frameworks/Python.framework/Versions/3.3/lib/python3.3/site-packages/django/template/base.py", line 140, in render
    return self._render(context)
  File "/Library/Frameworks/Python.framework/Versions/3.3/lib/python3.3/site-packages/django/template/base.py", line 134, in _render
    return self.nodelist.render(context)
  File "/Library/Frameworks/Python.framework/Versions/3.3/lib/python3.3/site-packages/django/template/base.py", line 830, in render
    bit = self.render_node(node, context)
  File "/Library/Frameworks/Python.framework/Versions/3.3/lib/python3.3/site-packages/django/template/debug.py", line 74, in render_node
    return node.render(context)
  File "/Library/Frameworks/Python.framework/Versions/3.3/lib/python3.3/site-packages/django/template/loader_tags.py", line 124, in render
    return compiled_parent._render(context)
  File "/Library/Frameworks/Python.framework/Versions/3.3/lib/python3.3/site-packages/django/template/base.py", line 134, in _render
    return self.nodelist.render(context)
  File "/Library/Frameworks/Python.framework/Versions/3.3/lib/python3.3/site-packages/django/template/base.py", line 830, in render
    bit = self.render_node(node, context)
  File "/Library/Frameworks/Python.framework/Versions/3.3/lib/python3.3/site-packages/django/template/debug.py", line 74, in render_node
    return node.render(context)
  File "/Library/Frameworks/Python.framework/Versions/3.3/lib/python3.3/site-packages/django/template/loader_tags.py", line 63, in render
    result = block.nodelist.render(context)
  File "/Library/Frameworks/Python.framework/Versions/3.3/lib/python3.3/site-packages/django/template/base.py", line 830, in render
    bit = self.render_node(node, context)
  File "/Library/Frameworks/Python.framework/Versions/3.3/lib/python3.3/site-packages/django/template/debug.py", line 74, in render_node
    return node.render(context)
  File "/Library/Frameworks/Python.framework/Versions/3.3/lib/python3.3/site-packages/django/template/defaulttags.py", line 189, in render
    nodelist.append(node.render(context))
  File "/Library/Frameworks/Python.framework/Versions/3.3/lib/python3.3/site-packages/django/template/defaulttags.py", line 426, in render
    raise e
  File "/Library/Frameworks/Python.framework/Versions/3.3/lib/python3.3/site-packages/django/template/defaulttags.py", line 413, in render
    url = reverse(view_name, args=args, kwargs=kwargs, current_app=context.current_app)
  File "/Library/Frameworks/Python.framework/Versions/3.3/lib/python3.3/site-packages/django/core/urlresolvers.py", line 496, in reverse
    return iri_to_uri(resolver._reverse_with_prefix(view, prefix, *args, **kwargs))
  File "/Library/Frameworks/Python.framework/Versions/3.3/lib/python3.3/site-packages/django/core/urlresolvers.py", line 416, in _reverse_with_prefix
    "arguments '%s' not found." % (lookup_view_s, args, kwargs))
django.core.urlresolvers.NoReverseMatch: Reverse for 'detail' with arguments '(1,)' and keyword arguments '{}' not found.
Internal Server Error: /posts
Traceback (most recent call last):
  File "/Library/Frameworks/Python.framework/Versions/3.3/lib/python3.3/site-packages/django/core/handlers/base.py", line 115, in get_response
    response = callback(request, *callback_args, **callback_kwargs)
  File "/Library/Frameworks/Python.framework/Versions/3.3/lib/python3.3/site-packages/django/views/generic/base.py", line 68, in view
    return self.dispatch(request, *args, **kwargs)
  File "/Library/Frameworks/Python.framework/Versions/3.3/lib/python3.3/site-packages/django/views/generic/base.py", line 86, in dispatch
    return handler(request, *args, **kwargs)
  File "/Library/Frameworks/Python.framework/Versions/3.3/lib/python3.3/site-packages/django/contrib/auth/decorators.py", line 24, in _wrapped_view
    if test_func(request.user):
AttributeError: 'IndexView' object has no attribute 'user'
Internal Server Error: /posts
Traceback (most recent call last):
  File "/Library/Frameworks/Python.framework/Versions/3.3/lib/python3.3/site-packages/django/core/handlers/base.py", line 114, in get_response
    response = wrapped_callback(request, *callback_args, **callback_kwargs)
  File "/Library/Frameworks/Python.framework/Versions/3.3/lib/python3.3/site-packages/django/views/generic/base.py", line 69, in view
    return self.dispatch(request, *args, **kwargs)
  File "/Library/Frameworks/Python.framework/Versions/3.3/lib/python3.3/site-packages/django/views/generic/base.py", line 87, in dispatch
    return handler(request, *args, **kwargs)
  File "/Library/Frameworks/Python.framework/Versions/3.3/lib/python3.3/site-packages/django/contrib/auth/decorators.py", line 21, in _wrapped_view
    if test_func(request.user):
AttributeError: 'IndexView' object has no attribute 'user'
Internal Server Error: /posts
Traceback (most recent call last):
  File "/Library/Frameworks/Python.framework/Versions/3.3/lib/python3.3/site-packages/django/core/handlers/base.py", line 114, in get_response
    response = wrapped_callback(request, *callback_args, **callback_kwargs)
  File "/Library/Frameworks/Python.framework/Versions/3.3/lib/python3.3/site-packages/django/views/generic/base.py", line 69, in view
    return self.dispatch(request, *args, **kwargs)
  File "/Library/Frameworks/Python.framework/Versions/3.3/lib/python3.3/site-packages/django/views/generic/base.py", line 87, in dispatch
    return handler(request, *args, **kwargs)
  File "/Library/Frameworks/Python.framework/Versions/3.3/lib/python3.3/site-packages/django/contrib/auth/decorators.py", line 21, in _wrapped_view
    if test_func(request.user):
AttributeError: 'IndexView' object has no attribute 'user'
Internal Server Error: /posts
Traceback (most recent call last):
  File "/Library/Frameworks/Python.framework/Versions/3.3/lib/python3.3/site-packages/django/core/handlers/base.py", line 114, in get_response
    response = wrapped_callback(request, *callback_args, **callback_kwargs)
  File "/Library/Frameworks/Python.framework/Versions/3.3/lib/python3.3/site-packages/django/views/generic/base.py", line 69, in view
    return self.dispatch(request, *args, **kwargs)
  File "/Library/Frameworks/Python.framework/Versions/3.3/lib/python3.3/site-packages/django/views/generic/base.py", line 87, in dispatch
    return handler(request, *args, **kwargs)
  File "/Library/Frameworks/Python.framework/Versions/3.3/lib/python3.3/site-packages/django/contrib/auth/decorators.py", line 21, in _wrapped_view
    if test_func(request.user):
AttributeError: 'IndexView' object has no attribute 'user'
Internal Server Error: /posts
Traceback (most recent call last):
  File "/Library/Frameworks/Python.framework/Versions/3.3/lib/python3.3/site-packages/django/core/handlers/base.py", line 114, in get_response
    response = wrapped_callback(request, *callback_args, **callback_kwargs)
  File "/Library/Frameworks/Python.framework/Versions/3.3/lib/python3.3/site-packages/django/views/generic/base.py", line 69, in view
    return self.dispatch(request, *args, **kwargs)
  File "/Library/Frameworks/Python.framework/Versions/3.3/lib/python3.3/site-packages/django/views/generic/base.py", line 87, in dispatch
    return handler(request, *args, **kwargs)
  File "/Library/Frameworks/Python.framework/Versions/3.3/lib/python3.3/site-packages/django/contrib/auth/decorators.py", line 21, in _wrapped_view
    if test_func(request.user):
AttributeError: 'IndexView' object has no attribute 'user'
Internal Server Error: /posts
Traceback (most recent call last):
  File "/Library/Frameworks/Python.framework/Versions/3.3/lib/python3.3/site-packages/django/core/handlers/base.py", line 114, in get_response
    response = wrapped_callback(request, *callback_args, **callback_kwargs)
  File "/Library/Frameworks/Python.framework/Versions/3.3/lib/python3.3/site-packages/django/views/generic/base.py", line 69, in view
    return self.dispatch(request, *args, **kwargs)
  File "/Library/Frameworks/Python.framework/Versions/3.3/lib/python3.3/site-packages/django/views/generic/base.py", line 87, in dispatch
    return handler(request, *args, **kwargs)
  File "/Library/Frameworks/Python.framework/Versions/3.3/lib/python3.3/site-packages/django/contrib/auth/decorators.py", line 21, in _wrapped_view
    if test_func(request.user):
AttributeError: 'IndexView' object has no attribute 'user'
Internal Server Error: /posts
Traceback (most recent call last):
  File "/Library/Frameworks/Python.framework/Versions/3.3/lib/python3.3/site-packages/django/core/handlers/base.py", line 114, in get_response
    response = wrapped_callback(request, *callback_args, **callback_kwargs)
  File "/Library/Frameworks/Python.framework/Versions/3.3/lib/python3.3/site-packages/django/views/generic/base.py", line 69, in view
    return self.dispatch(request, *args, **kwargs)
  File "/Library/Frameworks/Python.framework/Versions/3.3/lib/python3.3/site-packages/django/views/generic/base.py", line 87, in dispatch
    return handler(request, *args, **kwargs)
  File "/Library/Frameworks/Python.framework/Versions/3.3/lib/python3.3/site-packages/django/utils/decorators.py", line 29, in _wrapper
    return bound_func(*args, **kwargs)
  File "/Library/Frameworks/Python.framework/Versions/3.3/lib/python3.3/site-packages/django/contrib/auth/decorators.py", line 22, in _wrapped_view
    return view_func(request, *args, **kwargs)
  File "/Library/Frameworks/Python.framework/Versions/3.3/lib/python3.3/site-packages/django/utils/decorators.py", line 25, in bound_func
    return func(self, *args2, **kwargs2)
  File "/Users/never/PycharmProjects/bbs/posts/views.py", line 14, in get
    return render(request, "posts/posts.html", {'posts': Post.objects})
  File "/Library/Frameworks/Python.framework/Versions/3.3/lib/python3.3/site-packages/django/shortcuts/__init__.py", line 53, in render
    return HttpResponse(loader.render_to_string(*args, **kwargs),
  File "/Library/Frameworks/Python.framework/Versions/3.3/lib/python3.3/site-packages/django/template/loader.py", line 169, in render_to_string
    return t.render(context_instance)
  File "/Library/Frameworks/Python.framework/Versions/3.3/lib/python3.3/site-packages/django/template/base.py", line 140, in render
    return self._render(context)
  File "/Library/Frameworks/Python.framework/Versions/3.3/lib/python3.3/site-packages/django/template/base.py", line 134, in _render
    return self.nodelist.render(context)
  File "/Library/Frameworks/Python.framework/Versions/3.3/lib/python3.3/site-packages/django/template/base.py", line 840, in render
    bit = self.render_node(node, context)
  File "/Library/Frameworks/Python.framework/Versions/3.3/lib/python3.3/site-packages/django/template/debug.py", line 78, in render_node
    return node.render(context)
  File "/Library/Frameworks/Python.framework/Versions/3.3/lib/python3.3/site-packages/django/template/loader_tags.py", line 123, in render
    return compiled_parent._render(context)
  File "/Library/Frameworks/Python.framework/Versions/3.3/lib/python3.3/site-packages/django/template/base.py", line 134, in _render
    return self.nodelist.render(context)
  File "/Library/Frameworks/Python.framework/Versions/3.3/lib/python3.3/site-packages/django/template/base.py", line 840, in render
    bit = self.render_node(node, context)
  File "/Library/Frameworks/Python.framework/Versions/3.3/lib/python3.3/site-packages/django/template/debug.py", line 78, in render_node
    return node.render(context)
  File "/Library/Frameworks/Python.framework/Versions/3.3/lib/python3.3/site-packages/django/template/loader_tags.py", line 62, in render
    result = block.nodelist.render(context)
  File "/Library/Frameworks/Python.framework/Versions/3.3/lib/python3.3/site-packages/django/template/base.py", line 840, in render
    bit = self.render_node(node, context)
  File "/Library/Frameworks/Python.framework/Versions/3.3/lib/python3.3/site-packages/django/template/debug.py", line 78, in render_node
    return node.render(context)
  File "/Library/Frameworks/Python.framework/Versions/3.3/lib/python3.3/site-packages/django/template/defaulttags.py", line 155, in render
    values = list(values)
TypeError: 'Manager' object is not iterable
Internal Server Error: /posts
Traceback (most recent call last):
  File "/Library/Frameworks/Python.framework/Versions/3.3/lib/python3.3/site-packages/django/template/defaulttags.py", line 441, in render
    current_app=context.current_app)
  File "/Library/Frameworks/Python.framework/Versions/3.3/lib/python3.3/site-packages/django/core/urlresolvers.py", line 509, in reverse
    return iri_to_uri(resolver._reverse_with_prefix(view, prefix, *args, **kwargs))
  File "/Library/Frameworks/Python.framework/Versions/3.3/lib/python3.3/site-packages/django/core/urlresolvers.py", line 429, in _reverse_with_prefix
    (lookup_view_s, args, kwargs, len(patterns), patterns))
django.core.urlresolvers.NoReverseMatch: Reverse for 'bbs.detail' with arguments '(1,)' and keyword arguments '{}' not found. 0 pattern(s) tried: []

During handling of the above exception, another exception occurred:

Traceback (most recent call last):
  File "/Library/Frameworks/Python.framework/Versions/3.3/lib/python3.3/site-packages/django/core/handlers/base.py", line 114, in get_response
    response = wrapped_callback(request, *callback_args, **callback_kwargs)
  File "/Library/Frameworks/Python.framework/Versions/3.3/lib/python3.3/site-packages/django/views/generic/base.py", line 69, in view
    return self.dispatch(request, *args, **kwargs)
  File "/Library/Frameworks/Python.framework/Versions/3.3/lib/python3.3/site-packages/django/views/generic/base.py", line 87, in dispatch
    return handler(request, *args, **kwargs)
  File "/Library/Frameworks/Python.framework/Versions/3.3/lib/python3.3/site-packages/django/utils/decorators.py", line 29, in _wrapper
    return bound_func(*args, **kwargs)
  File "/Library/Frameworks/Python.framework/Versions/3.3/lib/python3.3/site-packages/django/contrib/auth/decorators.py", line 22, in _wrapped_view
    return view_func(request, *args, **kwargs)
  File "/Library/Frameworks/Python.framework/Versions/3.3/lib/python3.3/site-packages/django/utils/decorators.py", line 25, in bound_func
    return func(self, *args2, **kwargs2)
  File "/Users/never/PycharmProjects/bbs/posts/views.py", line 14, in get
    return render(request, "posts/posts.html", {'posts': Post.objects.all()})
  File "/Library/Frameworks/Python.framework/Versions/3.3/lib/python3.3/site-packages/django/shortcuts/__init__.py", line 53, in render
    return HttpResponse(loader.render_to_string(*args, **kwargs),
  File "/Library/Frameworks/Python.framework/Versions/3.3/lib/python3.3/site-packages/django/template/loader.py", line 169, in render_to_string
    return t.render(context_instance)
  File "/Library/Frameworks/Python.framework/Versions/3.3/lib/python3.3/site-packages/django/template/base.py", line 140, in render
    return self._render(context)
  File "/Library/Frameworks/Python.framework/Versions/3.3/lib/python3.3/site-packages/django/template/base.py", line 134, in _render
    return self.nodelist.render(context)
  File "/Library/Frameworks/Python.framework/Versions/3.3/lib/python3.3/site-packages/django/template/base.py", line 840, in render
    bit = self.render_node(node, context)
  File "/Library/Frameworks/Python.framework/Versions/3.3/lib/python3.3/site-packages/django/template/debug.py", line 78, in render_node
    return node.render(context)
  File "/Library/Frameworks/Python.framework/Versions/3.3/lib/python3.3/site-packages/django/template/loader_tags.py", line 123, in render
    return compiled_parent._render(context)
  File "/Library/Frameworks/Python.framework/Versions/3.3/lib/python3.3/site-packages/django/template/base.py", line 134, in _render
    return self.nodelist.render(context)
  File "/Library/Frameworks/Python.framework/Versions/3.3/lib/python3.3/site-packages/django/template/base.py", line 840, in render
    bit = self.render_node(node, context)
  File "/Library/Frameworks/Python.framework/Versions/3.3/lib/python3.3/site-packages/django/template/debug.py", line 78, in render_node
    return node.render(context)
  File "/Library/Frameworks/Python.framework/Versions/3.3/lib/python3.3/site-packages/django/template/loader_tags.py", line 62, in render
    result = block.nodelist.render(context)
  File "/Library/Frameworks/Python.framework/Versions/3.3/lib/python3.3/site-packages/django/template/base.py", line 840, in render
    bit = self.render_node(node, context)
  File "/Library/Frameworks/Python.framework/Versions/3.3/lib/python3.3/site-packages/django/template/debug.py", line 78, in render_node
    return node.render(context)
  File "/Library/Frameworks/Python.framework/Versions/3.3/lib/python3.3/site-packages/django/template/defaulttags.py", line 196, in render
    nodelist.append(node.render(context))
  File "/Library/Frameworks/Python.framework/Versions/3.3/lib/python3.3/site-packages/django/template/defaulttags.py", line 447, in render
    six.reraise(*exc_info)
  File "/Library/Frameworks/Python.framework/Versions/3.3/lib/python3.3/site-packages/django/utils/six.py", line 536, in reraise
    raise value
  File "/Library/Frameworks/Python.framework/Versions/3.3/lib/python3.3/site-packages/django/template/defaulttags.py", line 433, in render
    url = reverse(view_name, args=args, kwargs=kwargs, current_app=context.current_app)
  File "/Library/Frameworks/Python.framework/Versions/3.3/lib/python3.3/site-packages/django/core/urlresolvers.py", line 509, in reverse
    return iri_to_uri(resolver._reverse_with_prefix(view, prefix, *args, **kwargs))
  File "/Library/Frameworks/Python.framework/Versions/3.3/lib/python3.3/site-packages/django/core/urlresolvers.py", line 429, in _reverse_with_prefix
    (lookup_view_s, args, kwargs, len(patterns), patterns))
django.core.urlresolvers.NoReverseMatch: Reverse for 'detail' with arguments '(1,)' and keyword arguments '{}' not found. 0 pattern(s) tried: []
Internal Server Error: /posts
Traceback (most recent call last):
  File "/Library/Frameworks/Python.framework/Versions/3.3/lib/python3.3/site-packages/django/template/defaulttags.py", line 441, in render
    current_app=context.current_app)
  File "/Library/Frameworks/Python.framework/Versions/3.3/lib/python3.3/site-packages/django/core/urlresolvers.py", line 509, in reverse
    return iri_to_uri(resolver._reverse_with_prefix(view, prefix, *args, **kwargs))
  File "/Library/Frameworks/Python.framework/Versions/3.3/lib/python3.3/site-packages/django/core/urlresolvers.py", line 429, in _reverse_with_prefix
    (lookup_view_s, args, kwargs, len(patterns), patterns))
django.core.urlresolvers.NoReverseMatch: Reverse for 'bbs.detail' with arguments '(1,)' and keyword arguments '{}' not found. 0 pattern(s) tried: []

During handling of the above exception, another exception occurred:

Traceback (most recent call last):
  File "/Library/Frameworks/Python.framework/Versions/3.3/lib/python3.3/site-packages/django/core/handlers/base.py", line 114, in get_response
    response = wrapped_callback(request, *callback_args, **callback_kwargs)
  File "/Library/Frameworks/Python.framework/Versions/3.3/lib/python3.3/site-packages/django/views/generic/base.py", line 69, in view
    return self.dispatch(request, *args, **kwargs)
  File "/Library/Frameworks/Python.framework/Versions/3.3/lib/python3.3/site-packages/django/views/generic/base.py", line 87, in dispatch
    return handler(request, *args, **kwargs)
  File "/Library/Frameworks/Python.framework/Versions/3.3/lib/python3.3/site-packages/django/utils/decorators.py", line 29, in _wrapper
    return bound_func(*args, **kwargs)
  File "/Library/Frameworks/Python.framework/Versions/3.3/lib/python3.3/site-packages/django/contrib/auth/decorators.py", line 22, in _wrapped_view
    return view_func(request, *args, **kwargs)
  File "/Library/Frameworks/Python.framework/Versions/3.3/lib/python3.3/site-packages/django/utils/decorators.py", line 25, in bound_func
    return func(self, *args2, **kwargs2)
  File "/Users/never/PycharmProjects/bbs/posts/views.py", line 14, in get
    return render(request, "posts/posts.html", {'posts': Post.objects.all()})
  File "/Library/Frameworks/Python.framework/Versions/3.3/lib/python3.3/site-packages/django/shortcuts/__init__.py", line 53, in render
    return HttpResponse(loader.render_to_string(*args, **kwargs),
  File "/Library/Frameworks/Python.framework/Versions/3.3/lib/python3.3/site-packages/django/template/loader.py", line 169, in render_to_string
    return t.render(context_instance)
  File "/Library/Frameworks/Python.framework/Versions/3.3/lib/python3.3/site-packages/django/template/base.py", line 140, in render
    return self._render(context)
  File "/Library/Frameworks/Python.framework/Versions/3.3/lib/python3.3/site-packages/django/template/base.py", line 134, in _render
    return self.nodelist.render(context)
  File "/Library/Frameworks/Python.framework/Versions/3.3/lib/python3.3/site-packages/django/template/base.py", line 840, in render
    bit = self.render_node(node, context)
  File "/Library/Frameworks/Python.framework/Versions/3.3/lib/python3.3/site-packages/django/template/debug.py", line 78, in render_node
    return node.render(context)
  File "/Library/Frameworks/Python.framework/Versions/3.3/lib/python3.3/site-packages/django/template/loader_tags.py", line 123, in render
    return compiled_parent._render(context)
  File "/Library/Frameworks/Python.framework/Versions/3.3/lib/python3.3/site-packages/django/template/base.py", line 134, in _render
    return self.nodelist.render(context)
  File "/Library/Frameworks/Python.framework/Versions/3.3/lib/python3.3/site-packages/django/template/base.py", line 840, in render
    bit = self.render_node(node, context)
  File "/Library/Frameworks/Python.framework/Versions/3.3/lib/python3.3/site-packages/django/template/debug.py", line 78, in render_node
    return node.render(context)
  File "/Library/Frameworks/Python.framework/Versions/3.3/lib/python3.3/site-packages/django/template/loader_tags.py", line 62, in render
    result = block.nodelist.render(context)
  File "/Library/Frameworks/Python.framework/Versions/3.3/lib/python3.3/site-packages/django/template/base.py", line 840, in render
    bit = self.render_node(node, context)
  File "/Library/Frameworks/Python.framework/Versions/3.3/lib/python3.3/site-packages/django/template/debug.py", line 78, in render_node
    return node.render(context)
  File "/Library/Frameworks/Python.framework/Versions/3.3/lib/python3.3/site-packages/django/template/defaulttags.py", line 196, in render
    nodelist.append(node.render(context))
  File "/Library/Frameworks/Python.framework/Versions/3.3/lib/python3.3/site-packages/django/template/defaulttags.py", line 447, in render
    six.reraise(*exc_info)
  File "/Library/Frameworks/Python.framework/Versions/3.3/lib/python3.3/site-packages/django/utils/six.py", line 536, in reraise
    raise value
  File "/Library/Frameworks/Python.framework/Versions/3.3/lib/python3.3/site-packages/django/template/defaulttags.py", line 433, in render
    url = reverse(view_name, args=args, kwargs=kwargs, current_app=context.current_app)
  File "/Library/Frameworks/Python.framework/Versions/3.3/lib/python3.3/site-packages/django/core/urlresolvers.py", line 509, in reverse
    return iri_to_uri(resolver._reverse_with_prefix(view, prefix, *args, **kwargs))
  File "/Library/Frameworks/Python.framework/Versions/3.3/lib/python3.3/site-packages/django/core/urlresolvers.py", line 429, in _reverse_with_prefix
    (lookup_view_s, args, kwargs, len(patterns), patterns))
django.core.urlresolvers.NoReverseMatch: Reverse for 'detail' with arguments '(1,)' and keyword arguments '{}' not found. 0 pattern(s) tried: []
Internal Server Error: /posts
Traceback (most recent call last):
  File "/Library/Frameworks/Python.framework/Versions/3.3/lib/python3.3/site-packages/django/template/defaulttags.py", line 441, in render
    current_app=context.current_app)
  File "/Library/Frameworks/Python.framework/Versions/3.3/lib/python3.3/site-packages/django/core/urlresolvers.py", line 509, in reverse
    return iri_to_uri(resolver._reverse_with_prefix(view, prefix, *args, **kwargs))
  File "/Library/Frameworks/Python.framework/Versions/3.3/lib/python3.3/site-packages/django/core/urlresolvers.py", line 429, in _reverse_with_prefix
    (lookup_view_s, args, kwargs, len(patterns), patterns))
django.core.urlresolvers.NoReverseMatch: Reverse for 'bbs.detail' with arguments '(1,)' and keyword arguments '{}' not found. 0 pattern(s) tried: []

During handling of the above exception, another exception occurred:

Traceback (most recent call last):
  File "/Library/Frameworks/Python.framework/Versions/3.3/lib/python3.3/site-packages/django/core/handlers/base.py", line 114, in get_response
    response = wrapped_callback(request, *callback_args, **callback_kwargs)
  File "/Library/Frameworks/Python.framework/Versions/3.3/lib/python3.3/site-packages/django/views/generic/base.py", line 69, in view
    return self.dispatch(request, *args, **kwargs)
  File "/Library/Frameworks/Python.framework/Versions/3.3/lib/python3.3/site-packages/django/views/generic/base.py", line 87, in dispatch
    return handler(request, *args, **kwargs)
  File "/Library/Frameworks/Python.framework/Versions/3.3/lib/python3.3/site-packages/django/utils/decorators.py", line 29, in _wrapper
    return bound_func(*args, **kwargs)
  File "/Library/Frameworks/Python.framework/Versions/3.3/lib/python3.3/site-packages/django/contrib/auth/decorators.py", line 22, in _wrapped_view
    return view_func(request, *args, **kwargs)
  File "/Library/Frameworks/Python.framework/Versions/3.3/lib/python3.3/site-packages/django/utils/decorators.py", line 25, in bound_func
    return func(self, *args2, **kwargs2)
  File "/Users/never/PycharmProjects/bbs/posts/views.py", line 14, in get
    return render(request, "posts/posts.html", {'posts': Post.objects.all()})
  File "/Library/Frameworks/Python.framework/Versions/3.3/lib/python3.3/site-packages/django/shortcuts/__init__.py", line 53, in render
    return HttpResponse(loader.render_to_string(*args, **kwargs),
  File "/Library/Frameworks/Python.framework/Versions/3.3/lib/python3.3/site-packages/django/template/loader.py", line 169, in render_to_string
    return t.render(context_instance)
  File "/Library/Frameworks/Python.framework/Versions/3.3/lib/python3.3/site-packages/django/template/base.py", line 140, in render
    return self._render(context)
  File "/Library/Frameworks/Python.framework/Versions/3.3/lib/python3.3/site-packages/django/template/base.py", line 134, in _render
    return self.nodelist.render(context)
  File "/Library/Frameworks/Python.framework/Versions/3.3/lib/python3.3/site-packages/django/template/base.py", line 840, in render
    bit = self.render_node(node, context)
  File "/Library/Frameworks/Python.framework/Versions/3.3/lib/python3.3/site-packages/django/template/debug.py", line 78, in render_node
    return node.render(context)
  File "/Library/Frameworks/Python.framework/Versions/3.3/lib/python3.3/site-packages/django/template/loader_tags.py", line 123, in render
    return compiled_parent._render(context)
  File "/Library/Frameworks/Python.framework/Versions/3.3/lib/python3.3/site-packages/django/template/base.py", line 134, in _render
    return self.nodelist.render(context)
  File "/Library/Frameworks/Python.framework/Versions/3.3/lib/python3.3/site-packages/django/template/base.py", line 840, in render
    bit = self.render_node(node, context)
  File "/Library/Frameworks/Python.framework/Versions/3.3/lib/python3.3/site-packages/django/template/debug.py", line 78, in render_node
    return node.render(context)
  File "/Library/Frameworks/Python.framework/Versions/3.3/lib/python3.3/site-packages/django/template/loader_tags.py", line 62, in render
    result = block.nodelist.render(context)
  File "/Library/Frameworks/Python.framework/Versions/3.3/lib/python3.3/site-packages/django/template/base.py", line 840, in render
    bit = self.render_node(node, context)
  File "/Library/Frameworks/Python.framework/Versions/3.3/lib/python3.3/site-packages/django/template/debug.py", line 78, in render_node
    return node.render(context)
  File "/Library/Frameworks/Python.framework/Versions/3.3/lib/python3.3/site-packages/django/template/defaulttags.py", line 196, in render
    nodelist.append(node.render(context))
  File "/Library/Frameworks/Python.framework/Versions/3.3/lib/python3.3/site-packages/django/template/defaulttags.py", line 447, in render
    six.reraise(*exc_info)
  File "/Library/Frameworks/Python.framework/Versions/3.3/lib/python3.3/site-packages/django/utils/six.py", line 536, in reraise
    raise value
  File "/Library/Frameworks/Python.framework/Versions/3.3/lib/python3.3/site-packages/django/template/defaulttags.py", line 433, in render
    url = reverse(view_name, args=args, kwargs=kwargs, current_app=context.current_app)
  File "/Library/Frameworks/Python.framework/Versions/3.3/lib/python3.3/site-packages/django/core/urlresolvers.py", line 509, in reverse
    return iri_to_uri(resolver._reverse_with_prefix(view, prefix, *args, **kwargs))
  File "/Library/Frameworks/Python.framework/Versions/3.3/lib/python3.3/site-packages/django/core/urlresolvers.py", line 429, in _reverse_with_prefix
    (lookup_view_s, args, kwargs, len(patterns), patterns))
django.core.urlresolvers.NoReverseMatch: Reverse for 'detail' with arguments '(1,)' and keyword arguments '{}' not found. 0 pattern(s) tried: []
Internal Server Error: /posts
Traceback (most recent call last):
  File "/Library/Frameworks/Python.framework/Versions/3.3/lib/python3.3/site-packages/django/core/urlresolvers.py", line 384, in _reverse_with_prefix
    lookup_view = get_callable(lookup_view, True)
  File "/Library/Frameworks/Python.framework/Versions/3.3/lib/python3.3/site-packages/django/utils/functional.py", line 32, in wrapper
    result = func(*args)
  File "/Library/Frameworks/Python.framework/Versions/3.3/lib/python3.3/site-packages/django/core/urlresolvers.py", line 91, in get_callable
    mod_name, func_name = get_mod_func(lookup_view)
  File "/Library/Frameworks/Python.framework/Versions/3.3/lib/python3.3/site-packages/django/core/urlresolvers.py", line 141, in get_mod_func
    dot = callback.rindex('.')
AttributeError: 'int' object has no attribute 'rindex'

During handling of the above exception, another exception occurred:

Traceback (most recent call last):
  File "/Library/Frameworks/Python.framework/Versions/3.3/lib/python3.3/site-packages/django/template/defaulttags.py", line 433, in render
    url = reverse(view_name, args=args, kwargs=kwargs, current_app=context.current_app)
  File "/Library/Frameworks/Python.framework/Versions/3.3/lib/python3.3/site-packages/django/core/urlresolvers.py", line 509, in reverse
    return iri_to_uri(resolver._reverse_with_prefix(view, prefix, *args, **kwargs))
  File "/Library/Frameworks/Python.framework/Versions/3.3/lib/python3.3/site-packages/django/core/urlresolvers.py", line 386, in _reverse_with_prefix
    raise NoReverseMatch("Error importing '%s': %s." % (lookup_view, e))
django.core.urlresolvers.NoReverseMatch: Error importing '1': 'int' object has no attribute 'rindex'.

During handling of the above exception, another exception occurred:

Traceback (most recent call last):
  File "/Library/Frameworks/Python.framework/Versions/3.3/lib/python3.3/site-packages/django/core/handlers/base.py", line 114, in get_response
    response = wrapped_callback(request, *callback_args, **callback_kwargs)
  File "/Library/Frameworks/Python.framework/Versions/3.3/lib/python3.3/site-packages/django/views/generic/base.py", line 69, in view
    return self.dispatch(request, *args, **kwargs)
  File "/Library/Frameworks/Python.framework/Versions/3.3/lib/python3.3/site-packages/django/views/generic/base.py", line 87, in dispatch
    return handler(request, *args, **kwargs)
  File "/Library/Frameworks/Python.framework/Versions/3.3/lib/python3.3/site-packages/django/utils/decorators.py", line 29, in _wrapper
    return bound_func(*args, **kwargs)
  File "/Library/Frameworks/Python.framework/Versions/3.3/lib/python3.3/site-packages/django/contrib/auth/decorators.py", line 22, in _wrapped_view
    return view_func(request, *args, **kwargs)
  File "/Library/Frameworks/Python.framework/Versions/3.3/lib/python3.3/site-packages/django/utils/decorators.py", line 25, in bound_func
    return func(self, *args2, **kwargs2)
  File "/Users/never/PycharmProjects/bbs/posts/views.py", line 14, in get
    return render(request, "posts/posts.html", {'posts': Post.objects.all()})
  File "/Library/Frameworks/Python.framework/Versions/3.3/lib/python3.3/site-packages/django/shortcuts/__init__.py", line 53, in render
    return HttpResponse(loader.render_to_string(*args, **kwargs),
  File "/Library/Frameworks/Python.framework/Versions/3.3/lib/python3.3/site-packages/django/template/loader.py", line 169, in render_to_string
    return t.render(context_instance)
  File "/Library/Frameworks/Python.framework/Versions/3.3/lib/python3.3/site-packages/django/template/base.py", line 140, in render
    return self._render(context)
  File "/Library/Frameworks/Python.framework/Versions/3.3/lib/python3.3/site-packages/django/template/base.py", line 134, in _render
    return self.nodelist.render(context)
  File "/Library/Frameworks/Python.framework/Versions/3.3/lib/python3.3/site-packages/django/template/base.py", line 840, in render
    bit = self.render_node(node, context)
  File "/Library/Frameworks/Python.framework/Versions/3.3/lib/python3.3/site-packages/django/template/debug.py", line 78, in render_node
    return node.render(context)
  File "/Library/Frameworks/Python.framework/Versions/3.3/lib/python3.3/site-packages/django/template/loader_tags.py", line 123, in render
    return compiled_parent._render(context)
  File "/Library/Frameworks/Python.framework/Versions/3.3/lib/python3.3/site-packages/django/template/base.py", line 134, in _render
    return self.nodelist.render(context)
  File "/Library/Frameworks/Python.framework/Versions/3.3/lib/python3.3/site-packages/django/template/base.py", line 840, in render
    bit = self.render_node(node, context)
  File "/Library/Frameworks/Python.framework/Versions/3.3/lib/python3.3/site-packages/django/template/debug.py", line 78, in render_node
    return node.render(context)
  File "/Library/Frameworks/Python.framework/Versions/3.3/lib/python3.3/site-packages/django/template/loader_tags.py", line 62, in render
    result = block.nodelist.render(context)
  File "/Library/Frameworks/Python.framework/Versions/3.3/lib/python3.3/site-packages/django/template/base.py", line 840, in render
    bit = self.render_node(node, context)
  File "/Library/Frameworks/Python.framework/Versions/3.3/lib/python3.3/site-packages/django/template/debug.py", line 78, in render_node
    return node.render(context)
  File "/Library/Frameworks/Python.framework/Versions/3.3/lib/python3.3/site-packages/django/template/defaulttags.py", line 196, in render
    nodelist.append(node.render(context))
  File "/Library/Frameworks/Python.framework/Versions/3.3/lib/python3.3/site-packages/django/template/defaulttags.py", line 439, in render
    url = reverse(project_name + '.' + view_name,
TypeError: Can't convert 'int' object to str implicitly
Internal Server Error: /posts
Traceback (most recent call last):
  File "/Library/Frameworks/Python.framework/Versions/3.3/lib/python3.3/site-packages/django/template/defaulttags.py", line 441, in render
    current_app=context.current_app)
  File "/Library/Frameworks/Python.framework/Versions/3.3/lib/python3.3/site-packages/django/core/urlresolvers.py", line 509, in reverse
    return iri_to_uri(resolver._reverse_with_prefix(view, prefix, *args, **kwargs))
  File "/Library/Frameworks/Python.framework/Versions/3.3/lib/python3.3/site-packages/django/core/urlresolvers.py", line 429, in _reverse_with_prefix
    (lookup_view_s, args, kwargs, len(patterns), patterns))
django.core.urlresolvers.NoReverseMatch: Reverse for 'bbs.post.id' with arguments '()' and keyword arguments '{}' not found. 0 pattern(s) tried: []

During handling of the above exception, another exception occurred:

Traceback (most recent call last):
  File "/Library/Frameworks/Python.framework/Versions/3.3/lib/python3.3/site-packages/django/core/handlers/base.py", line 114, in get_response
    response = wrapped_callback(request, *callback_args, **callback_kwargs)
  File "/Library/Frameworks/Python.framework/Versions/3.3/lib/python3.3/site-packages/django/views/generic/base.py", line 69, in view
    return self.dispatch(request, *args, **kwargs)
  File "/Library/Frameworks/Python.framework/Versions/3.3/lib/python3.3/site-packages/django/views/generic/base.py", line 87, in dispatch
    return handler(request, *args, **kwargs)
  File "/Library/Frameworks/Python.framework/Versions/3.3/lib/python3.3/site-packages/django/utils/decorators.py", line 29, in _wrapper
    return bound_func(*args, **kwargs)
  File "/Library/Frameworks/Python.framework/Versions/3.3/lib/python3.3/site-packages/django/contrib/auth/decorators.py", line 22, in _wrapped_view
    return view_func(request, *args, **kwargs)
  File "/Library/Frameworks/Python.framework/Versions/3.3/lib/python3.3/site-packages/django/utils/decorators.py", line 25, in bound_func
    return func(self, *args2, **kwargs2)
  File "/Users/never/PycharmProjects/bbs/posts/views.py", line 14, in get
    return render(request, "posts/posts.html", {'posts': Post.objects.all()})
  File "/Library/Frameworks/Python.framework/Versions/3.3/lib/python3.3/site-packages/django/shortcuts/__init__.py", line 53, in render
    return HttpResponse(loader.render_to_string(*args, **kwargs),
  File "/Library/Frameworks/Python.framework/Versions/3.3/lib/python3.3/site-packages/django/template/loader.py", line 169, in render_to_string
    return t.render(context_instance)
  File "/Library/Frameworks/Python.framework/Versions/3.3/lib/python3.3/site-packages/django/template/base.py", line 140, in render
    return self._render(context)
  File "/Library/Frameworks/Python.framework/Versions/3.3/lib/python3.3/site-packages/django/template/base.py", line 134, in _render
    return self.nodelist.render(context)
  File "/Library/Frameworks/Python.framework/Versions/3.3/lib/python3.3/site-packages/django/template/base.py", line 840, in render
    bit = self.render_node(node, context)
  File "/Library/Frameworks/Python.framework/Versions/3.3/lib/python3.3/site-packages/django/template/debug.py", line 78, in render_node
    return node.render(context)
  File "/Library/Frameworks/Python.framework/Versions/3.3/lib/python3.3/site-packages/django/template/loader_tags.py", line 123, in render
    return compiled_parent._render(context)
  File "/Library/Frameworks/Python.framework/Versions/3.3/lib/python3.3/site-packages/django/template/base.py", line 134, in _render
    return self.nodelist.render(context)
  File "/Library/Frameworks/Python.framework/Versions/3.3/lib/python3.3/site-packages/django/template/base.py", line 840, in render
    bit = self.render_node(node, context)
  File "/Library/Frameworks/Python.framework/Versions/3.3/lib/python3.3/site-packages/django/template/debug.py", line 78, in render_node
    return node.render(context)
  File "/Library/Frameworks/Python.framework/Versions/3.3/lib/python3.3/site-packages/django/template/loader_tags.py", line 62, in render
    result = block.nodelist.render(context)
  File "/Library/Frameworks/Python.framework/Versions/3.3/lib/python3.3/site-packages/django/template/base.py", line 840, in render
    bit = self.render_node(node, context)
  File "/Library/Frameworks/Python.framework/Versions/3.3/lib/python3.3/site-packages/django/template/debug.py", line 78, in render_node
    return node.render(context)
  File "/Library/Frameworks/Python.framework/Versions/3.3/lib/python3.3/site-packages/django/template/defaulttags.py", line 196, in render
    nodelist.append(node.render(context))
  File "/Library/Frameworks/Python.framework/Versions/3.3/lib/python3.3/site-packages/django/template/defaulttags.py", line 447, in render
    six.reraise(*exc_info)
  File "/Library/Frameworks/Python.framework/Versions/3.3/lib/python3.3/site-packages/django/utils/six.py", line 536, in reraise
    raise value
  File "/Library/Frameworks/Python.framework/Versions/3.3/lib/python3.3/site-packages/django/template/defaulttags.py", line 433, in render
    url = reverse(view_name, args=args, kwargs=kwargs, current_app=context.current_app)
  File "/Library/Frameworks/Python.framework/Versions/3.3/lib/python3.3/site-packages/django/core/urlresolvers.py", line 509, in reverse
    return iri_to_uri(resolver._reverse_with_prefix(view, prefix, *args, **kwargs))
  File "/Library/Frameworks/Python.framework/Versions/3.3/lib/python3.3/site-packages/django/core/urlresolvers.py", line 429, in _reverse_with_prefix
    (lookup_view_s, args, kwargs, len(patterns), patterns))
django.core.urlresolvers.NoReverseMatch: Reverse for 'post.id' with arguments '()' and keyword arguments '{}' not found. 0 pattern(s) tried: []
Method Not Allowed (GET): /posts/1
Method Not Allowed (GET): /posts/1
Internal Server Error: /admin/posts/post/1/history/
Traceback (most recent call last):
  File "/Library/Frameworks/Python.framework/Versions/3.3/lib/python3.3/site-packages/django/core/urlresolvers.py", line 339, in urlconf_module
    return self._urlconf_module
AttributeError: 'RegexURLResolver' object has no attribute '_urlconf_module'

During handling of the above exception, another exception occurred:

Traceback (most recent call last):
  File "/Library/Frameworks/Python.framework/Versions/3.3/lib/python3.3/site-packages/django/core/handlers/base.py", line 101, in get_response
    resolver_match = resolver.resolve(request.path_info)
  File "/Library/Frameworks/Python.framework/Versions/3.3/lib/python3.3/site-packages/django/core/urlresolvers.py", line 318, in resolve
    for pattern in self.url_patterns:
  File "/Library/Frameworks/Python.framework/Versions/3.3/lib/python3.3/site-packages/django/core/urlresolvers.py", line 346, in url_patterns
    patterns = getattr(self.urlconf_module, "urlpatterns", self.urlconf_module)
  File "/Library/Frameworks/Python.framework/Versions/3.3/lib/python3.3/site-packages/django/core/urlresolvers.py", line 341, in urlconf_module
    self._urlconf_module = import_module(self.urlconf_name)
  File "/Library/Frameworks/Python.framework/Versions/3.3/lib/python3.3/importlib/__init__.py", line 90, in import_module
    return _bootstrap._gcd_import(name[level:], package, level)
  File "<frozen importlib._bootstrap>", line 1584, in _gcd_import
  File "<frozen importlib._bootstrap>", line 1565, in _find_and_load
  File "<frozen importlib._bootstrap>", line 1532, in _find_and_load_unlocked
  File "<frozen importlib._bootstrap>", line 584, in _check_name_wrapper
  File "<frozen importlib._bootstrap>", line 1022, in load_module
  File "<frozen importlib._bootstrap>", line 1003, in load_module
  File "<frozen importlib._bootstrap>", line 560, in module_for_loader_wrapper
  File "<frozen importlib._bootstrap>", line 868, in _load_module
  File "<frozen importlib._bootstrap>", line 313, in _call_with_frames_removed
  File "/Users/never/PycharmProjects/bbs/bbs/urls.py", line 22, in <module>
    url(r'^posts/?', include('posts.urls', namespace="posts")),
  File "/Library/Frameworks/Python.framework/Versions/3.3/lib/python3.3/site-packages/django/conf/urls/__init__.py", line 26, in include
    urlconf_module = import_module(urlconf_module)
  File "/Library/Frameworks/Python.framework/Versions/3.3/lib/python3.3/importlib/__init__.py", line 90, in import_module
    return _bootstrap._gcd_import(name[level:], package, level)
  File "<frozen importlib._bootstrap>", line 1584, in _gcd_import
  File "<frozen importlib._bootstrap>", line 1565, in _find_and_load
  File "<frozen importlib._bootstrap>", line 1532, in _find_and_load_unlocked
  File "<frozen importlib._bootstrap>", line 584, in _check_name_wrapper
  File "<frozen importlib._bootstrap>", line 1022, in load_module
  File "<frozen importlib._bootstrap>", line 1003, in load_module
  File "<frozen importlib._bootstrap>", line 560, in module_for_loader_wrapper
  File "<frozen importlib._bootstrap>", line 868, in _load_module
  File "<frozen importlib._bootstrap>", line 313, in _call_with_frames_removed
  File "/Users/never/PycharmProjects/bbs/posts/urls.py", line 3, in <module>
    from posts import views
  File "/Users/never/PycharmProjects/bbs/posts/views.py", line 27
    def update(self, request):
      ^
IndentationError: expected an indented block
Internal Server Error: /admin/
Traceback (most recent call last):
  File "/Library/Frameworks/Python.framework/Versions/3.3/lib/python3.3/site-packages/django/core/urlresolvers.py", line 339, in urlconf_module
    return self._urlconf_module
AttributeError: 'RegexURLResolver' object has no attribute '_urlconf_module'

During handling of the above exception, another exception occurred:

Traceback (most recent call last):
  File "/Library/Frameworks/Python.framework/Versions/3.3/lib/python3.3/site-packages/django/core/handlers/base.py", line 101, in get_response
    resolver_match = resolver.resolve(request.path_info)
  File "/Library/Frameworks/Python.framework/Versions/3.3/lib/python3.3/site-packages/django/core/urlresolvers.py", line 318, in resolve
    for pattern in self.url_patterns:
  File "/Library/Frameworks/Python.framework/Versions/3.3/lib/python3.3/site-packages/django/core/urlresolvers.py", line 346, in url_patterns
    patterns = getattr(self.urlconf_module, "urlpatterns", self.urlconf_module)
  File "/Library/Frameworks/Python.framework/Versions/3.3/lib/python3.3/site-packages/django/core/urlresolvers.py", line 341, in urlconf_module
    self._urlconf_module = import_module(self.urlconf_name)
  File "/Library/Frameworks/Python.framework/Versions/3.3/lib/python3.3/importlib/__init__.py", line 90, in import_module
    return _bootstrap._gcd_import(name[level:], package, level)
  File "<frozen importlib._bootstrap>", line 1584, in _gcd_import
  File "<frozen importlib._bootstrap>", line 1565, in _find_and_load
  File "<frozen importlib._bootstrap>", line 1532, in _find_and_load_unlocked
  File "<frozen importlib._bootstrap>", line 584, in _check_name_wrapper
  File "<frozen importlib._bootstrap>", line 1022, in load_module
  File "<frozen importlib._bootstrap>", line 1003, in load_module
  File "<frozen importlib._bootstrap>", line 560, in module_for_loader_wrapper
  File "<frozen importlib._bootstrap>", line 868, in _load_module
  File "<frozen importlib._bootstrap>", line 313, in _call_with_frames_removed
  File "/Users/never/PycharmProjects/bbs/bbs/urls.py", line 22, in <module>
    url(r'^posts/?', include('posts.urls', namespace="posts")),
  File "/Library/Frameworks/Python.framework/Versions/3.3/lib/python3.3/site-packages/django/conf/urls/__init__.py", line 26, in include
    urlconf_module = import_module(urlconf_module)
  File "/Library/Frameworks/Python.framework/Versions/3.3/lib/python3.3/importlib/__init__.py", line 90, in import_module
    return _bootstrap._gcd_import(name[level:], package, level)
  File "<frozen importlib._bootstrap>", line 1584, in _gcd_import
  File "<frozen importlib._bootstrap>", line 1565, in _find_and_load
  File "<frozen importlib._bootstrap>", line 1532, in _find_and_load_unlocked
  File "<frozen importlib._bootstrap>", line 584, in _check_name_wrapper
  File "<frozen importlib._bootstrap>", line 1022, in load_module
  File "<frozen importlib._bootstrap>", line 1003, in load_module
  File "<frozen importlib._bootstrap>", line 560, in module_for_loader_wrapper
  File "<frozen importlib._bootstrap>", line 868, in _load_module
  File "<frozen importlib._bootstrap>", line 313, in _call_with_frames_removed
  File "/Users/never/PycharmProjects/bbs/posts/urls.py", line 3, in <module>
    from posts import views
  File "/Users/never/PycharmProjects/bbs/posts/views.py", line 27
    def update(self, request):
      ^
IndentationError: expected an indented block
Internal Server Error: /admin/
Traceback (most recent call last):
  File "/Library/Frameworks/Python.framework/Versions/3.3/lib/python3.3/site-packages/django/core/urlresolvers.py", line 339, in urlconf_module
    return self._urlconf_module
AttributeError: 'RegexURLResolver' object has no attribute '_urlconf_module'

During handling of the above exception, another exception occurred:

Traceback (most recent call last):
  File "/Library/Frameworks/Python.framework/Versions/3.3/lib/python3.3/site-packages/django/core/handlers/base.py", line 101, in get_response
    resolver_match = resolver.resolve(request.path_info)
  File "/Library/Frameworks/Python.framework/Versions/3.3/lib/python3.3/site-packages/django/core/urlresolvers.py", line 318, in resolve
    for pattern in self.url_patterns:
  File "/Library/Frameworks/Python.framework/Versions/3.3/lib/python3.3/site-packages/django/core/urlresolvers.py", line 346, in url_patterns
    patterns = getattr(self.urlconf_module, "urlpatterns", self.urlconf_module)
  File "/Library/Frameworks/Python.framework/Versions/3.3/lib/python3.3/site-packages/django/core/urlresolvers.py", line 341, in urlconf_module
    self._urlconf_module = import_module(self.urlconf_name)
  File "/Library/Frameworks/Python.framework/Versions/3.3/lib/python3.3/importlib/__init__.py", line 90, in import_module
    return _bootstrap._gcd_import(name[level:], package, level)
  File "<frozen importlib._bootstrap>", line 1584, in _gcd_import
  File "<frozen importlib._bootstrap>", line 1565, in _find_and_load
  File "<frozen importlib._bootstrap>", line 1532, in _find_and_load_unlocked
  File "<frozen importlib._bootstrap>", line 584, in _check_name_wrapper
  File "<frozen importlib._bootstrap>", line 1022, in load_module
  File "<frozen importlib._bootstrap>", line 1003, in load_module
  File "<frozen importlib._bootstrap>", line 560, in module_for_loader_wrapper
  File "<frozen importlib._bootstrap>", line 868, in _load_module
  File "<frozen importlib._bootstrap>", line 313, in _call_with_frames_removed
  File "/Users/never/PycharmProjects/bbs/bbs/urls.py", line 22, in <module>
    url(r'^posts/?', include('posts.urls', namespace="posts")),
  File "/Library/Frameworks/Python.framework/Versions/3.3/lib/python3.3/site-packages/django/conf/urls/__init__.py", line 26, in include
    urlconf_module = import_module(urlconf_module)
  File "/Library/Frameworks/Python.framework/Versions/3.3/lib/python3.3/importlib/__init__.py", line 90, in import_module
    return _bootstrap._gcd_import(name[level:], package, level)
  File "<frozen importlib._bootstrap>", line 1584, in _gcd_import
  File "<frozen importlib._bootstrap>", line 1565, in _find_and_load
  File "<frozen importlib._bootstrap>", line 1532, in _find_and_load_unlocked
  File "<frozen importlib._bootstrap>", line 584, in _check_name_wrapper
  File "<frozen importlib._bootstrap>", line 1022, in load_module
  File "<frozen importlib._bootstrap>", line 1003, in load_module
  File "<frozen importlib._bootstrap>", line 560, in module_for_loader_wrapper
  File "<frozen importlib._bootstrap>", line 868, in _load_module
  File "<frozen importlib._bootstrap>", line 313, in _call_with_frames_removed
  File "/Users/never/PycharmProjects/bbs/posts/urls.py", line 7, in <module>
    url(r'^new/$', views.NewPostView.as_view(), name='index'),
AttributeError: 'module' object has no attribute 'NewPostView'
Internal Server Error: /posts/1
Traceback (most recent call last):
  File "/Library/Frameworks/Python.framework/Versions/3.3/lib/python3.3/site-packages/django/core/handlers/base.py", line 114, in get_response
    response = wrapped_callback(request, *callback_args, **callback_kwargs)
  File "/Library/Frameworks/Python.framework/Versions/3.3/lib/python3.3/site-packages/django/views/generic/base.py", line 69, in view
    return self.dispatch(request, *args, **kwargs)
  File "/Library/Frameworks/Python.framework/Versions/3.3/lib/python3.3/site-packages/django/views/generic/base.py", line 87, in dispatch
    return handler(request, *args, **kwargs)
  File "/Library/Frameworks/Python.framework/Versions/3.3/lib/python3.3/site-packages/django/utils/decorators.py", line 29, in _wrapper
    return bound_func(*args, **kwargs)
  File "/Library/Frameworks/Python.framework/Versions/3.3/lib/python3.3/site-packages/django/contrib/auth/decorators.py", line 22, in _wrapped_view
    return view_func(request, *args, **kwargs)
  File "/Library/Frameworks/Python.framework/Versions/3.3/lib/python3.3/site-packages/django/utils/decorators.py", line 25, in bound_func
    return func(self, *args2, **kwargs2)
  File "/Users/never/PycharmProjects/bbs/posts/views.py", line 22, in get
    replys = Reply.objects.get(post=post_id)
  File "/Library/Frameworks/Python.framework/Versions/3.3/lib/python3.3/site-packages/django/db/models/manager.py", line 151, in get
    return self.get_queryset().get(*args, **kwargs)
  File "/Library/Frameworks/Python.framework/Versions/3.3/lib/python3.3/site-packages/django/db/models/query.py", line 310, in get
    (self.model._meta.object_name, num))
posts.models.MultipleObjectsReturned: get() returned more than one Reply -- it returned 2!
Internal Server Error: /posts/1
Traceback (most recent call last):
  File "/Library/Frameworks/Python.framework/Versions/3.3/lib/python3.3/site-packages/django/core/handlers/base.py", line 114, in get_response
    response = wrapped_callback(request, *callback_args, **callback_kwargs)
  File "/Library/Frameworks/Python.framework/Versions/3.3/lib/python3.3/site-packages/django/views/generic/base.py", line 69, in view
    return self.dispatch(request, *args, **kwargs)
  File "/Library/Frameworks/Python.framework/Versions/3.3/lib/python3.3/site-packages/django/views/generic/base.py", line 87, in dispatch
    return handler(request, *args, **kwargs)
  File "/Library/Frameworks/Python.framework/Versions/3.3/lib/python3.3/site-packages/django/utils/decorators.py", line 29, in _wrapper
    return bound_func(*args, **kwargs)
  File "/Library/Frameworks/Python.framework/Versions/3.3/lib/python3.3/site-packages/django/contrib/auth/decorators.py", line 22, in _wrapped_view
    return view_func(request, *args, **kwargs)
  File "/Library/Frameworks/Python.framework/Versions/3.3/lib/python3.3/site-packages/django/utils/decorators.py", line 25, in bound_func
    return func(self, *args2, **kwargs2)
  File "/Users/never/PycharmProjects/bbs/posts/views.py", line 22, in get
    replys = Reply.objects.get_query_set(post=post_id)
  File "/Library/Frameworks/Python.framework/Versions/3.3/lib/python3.3/site-packages/django/utils/deprecation.py", line 18, in wrapped
    return f(*args, **kwargs)
TypeError: get_queryset() got an unexpected keyword argument 'post'
Internal Server Error: /posts/1
Traceback (most recent call last):
  File "/Library/Frameworks/Python.framework/Versions/3.3/lib/python3.3/site-packages/django/core/handlers/base.py", line 114, in get_response
    response = wrapped_callback(request, *callback_args, **callback_kwargs)
  File "/Library/Frameworks/Python.framework/Versions/3.3/lib/python3.3/site-packages/django/views/generic/base.py", line 69, in view
    return self.dispatch(request, *args, **kwargs)
  File "/Library/Frameworks/Python.framework/Versions/3.3/lib/python3.3/site-packages/django/views/generic/base.py", line 87, in dispatch
    return handler(request, *args, **kwargs)
  File "/Library/Frameworks/Python.framework/Versions/3.3/lib/python3.3/site-packages/django/utils/decorators.py", line 29, in _wrapper
    return bound_func(*args, **kwargs)
  File "/Library/Frameworks/Python.framework/Versions/3.3/lib/python3.3/site-packages/django/contrib/auth/decorators.py", line 22, in _wrapped_view
    return view_func(request, *args, **kwargs)
  File "/Library/Frameworks/Python.framework/Versions/3.3/lib/python3.3/site-packages/django/utils/decorators.py", line 25, in bound_func
    return func(self, *args2, **kwargs2)
  File "/Users/never/PycharmProjects/bbs/posts/views.py", line 22, in get
    replys = Reply.objects.get(post=post_id)
  File "/Library/Frameworks/Python.framework/Versions/3.3/lib/python3.3/site-packages/django/db/models/manager.py", line 151, in get
    return self.get_queryset().get(*args, **kwargs)
  File "/Library/Frameworks/Python.framework/Versions/3.3/lib/python3.3/site-packages/django/db/models/query.py", line 310, in get
    (self.model._meta.object_name, num))
posts.models.MultipleObjectsReturned: get() returned more than one Reply -- it returned 2!
Internal Server Error: /posts/2
Traceback (most recent call last):
  File "/Library/Frameworks/Python.framework/Versions/3.3/lib/python3.3/site-packages/django/core/handlers/base.py", line 114, in get_response
    response = wrapped_callback(request, *callback_args, **callback_kwargs)
  File "/Library/Frameworks/Python.framework/Versions/3.3/lib/python3.3/site-packages/django/views/generic/base.py", line 69, in view
    return self.dispatch(request, *args, **kwargs)
  File "/Library/Frameworks/Python.framework/Versions/3.3/lib/python3.3/site-packages/django/views/generic/base.py", line 87, in dispatch
    return handler(request, *args, **kwargs)
  File "/Library/Frameworks/Python.framework/Versions/3.3/lib/python3.3/site-packages/django/utils/decorators.py", line 29, in _wrapper
    return bound_func(*args, **kwargs)
  File "/Library/Frameworks/Python.framework/Versions/3.3/lib/python3.3/site-packages/django/contrib/auth/decorators.py", line 22, in _wrapped_view
    return view_func(request, *args, **kwargs)
  File "/Library/Frameworks/Python.framework/Versions/3.3/lib/python3.3/site-packages/django/utils/decorators.py", line 25, in bound_func
    return func(self, *args2, **kwargs2)
  File "/Users/never/PycharmProjects/bbs/posts/views.py", line 23, in get
    return render(request, "posts/detail.html", {'post': post, 'replys': replys, 'user_id': self.request.user, 'title': post.title})
AttributeError: 'QuerySet' object has no attribute 'title'
Internal Server Error: /
Traceback (most recent call last):
  File "/Library/Frameworks/Python.framework/Versions/3.3/lib/python3.3/site-packages/django/contrib/sessions/backends/base.py", line 168, in _get_session
    return self._session_cache
AttributeError: 'SessionStore' object has no attribute '_session_cache'

During handling of the above exception, another exception occurred:

Traceback (most recent call last):
  File "/Library/Frameworks/Python.framework/Versions/3.3/lib/python3.3/site-packages/django/db/backends/__init__.py", line 124, in ensure_connection
    self.connect()
  File "/Library/Frameworks/Python.framework/Versions/3.3/lib/python3.3/site-packages/django/db/backends/__init__.py", line 112, in connect
    self.connection = self.get_new_connection(conn_params)
  File "/Library/Frameworks/Python.framework/Versions/3.3/lib/python3.3/site-packages/django/db/backends/mysql/base.py", line 435, in get_new_connection
    conn = Database.connect(**conn_params)
  File "/Library/Frameworks/Python.framework/Versions/3.3/lib/python3.3/site-packages/MySQL_python-1.2.3-py3.3-macosx-10.6-intel.egg/MySQLdb/__init__.py", line 81, in Connect
    return Connection(*args, **kwargs)
  File "/Library/Frameworks/Python.framework/Versions/3.3/lib/python3.3/site-packages/MySQL_python-1.2.3-py3.3-macosx-10.6-intel.egg/MySQLdb/connections.py", line 175, in __init__
    super(Connection, self).__init__(*args, **kwargs2)
_mysql_exceptions.OperationalError: (2003, "Can't connect to MySQL server on '127.0.0.1' (61)")

The above exception was the direct cause of the following exception:

Traceback (most recent call last):
  File "/Library/Frameworks/Python.framework/Versions/3.3/lib/python3.3/site-packages/django/core/handlers/base.py", line 114, in get_response
    response = wrapped_callback(request, *callback_args, **callback_kwargs)
  File "/Library/Frameworks/Python.framework/Versions/3.3/lib/python3.3/site-packages/django/views/generic/base.py", line 69, in view
    return self.dispatch(request, *args, **kwargs)
  File "/Library/Frameworks/Python.framework/Versions/3.3/lib/python3.3/site-packages/django/views/generic/base.py", line 87, in dispatch
    return handler(request, *args, **kwargs)
  File "/Users/never/PycharmProjects/bbs/bbs/views.py", line 12, in get
    if request.user.is_authenticated():
  File "/Library/Frameworks/Python.framework/Versions/3.3/lib/python3.3/site-packages/django/utils/functional.py", line 213, in inner
    self._setup()
  File "/Library/Frameworks/Python.framework/Versions/3.3/lib/python3.3/site-packages/django/utils/functional.py", line 298, in _setup
    self._wrapped = self._setupfunc()
  File "/Library/Frameworks/Python.framework/Versions/3.3/lib/python3.3/site-packages/django/contrib/auth/middleware.py", line 18, in <lambda>
    request.user = SimpleLazyObject(lambda: get_user(request))
  File "/Library/Frameworks/Python.framework/Versions/3.3/lib/python3.3/site-packages/django/contrib/auth/middleware.py", line 10, in get_user
    request._cached_user = auth.get_user(request)
  File "/Library/Frameworks/Python.framework/Versions/3.3/lib/python3.3/site-packages/django/contrib/auth/__init__.py", line 140, in get_user
    user_id = request.session[SESSION_KEY]
  File "/Library/Frameworks/Python.framework/Versions/3.3/lib/python3.3/site-packages/django/contrib/sessions/backends/base.py", line 47, in __getitem__
    return self._session[key]
  File "/Library/Frameworks/Python.framework/Versions/3.3/lib/python3.3/site-packages/django/contrib/sessions/backends/base.py", line 173, in _get_session
    self._session_cache = self.load()
  File "/Library/Frameworks/Python.framework/Versions/3.3/lib/python3.3/site-packages/django/contrib/sessions/backends/db.py", line 20, in load
    expire_date__gt=timezone.now()
  File "/Library/Frameworks/Python.framework/Versions/3.3/lib/python3.3/site-packages/django/db/models/manager.py", line 151, in get
    return self.get_queryset().get(*args, **kwargs)
  File "/Library/Frameworks/Python.framework/Versions/3.3/lib/python3.3/site-packages/django/db/models/query.py", line 301, in get
    num = len(clone)
  File "/Library/Frameworks/Python.framework/Versions/3.3/lib/python3.3/site-packages/django/db/models/query.py", line 77, in __len__
    self._fetch_all()
  File "/Library/Frameworks/Python.framework/Versions/3.3/lib/python3.3/site-packages/django/db/models/query.py", line 854, in _fetch_all
    self._result_cache = list(self.iterator())
  File "/Library/Frameworks/Python.framework/Versions/3.3/lib/python3.3/site-packages/django/db/models/query.py", line 220, in iterator
    for row in compiler.results_iter():
  File "/Library/Frameworks/Python.framework/Versions/3.3/lib/python3.3/site-packages/django/db/models/sql/compiler.py", line 709, in results_iter
    for rows in self.execute_sql(MULTI):
  File "/Library/Frameworks/Python.framework/Versions/3.3/lib/python3.3/site-packages/django/db/models/sql/compiler.py", line 781, in execute_sql
    cursor = self.connection.cursor()
  File "/Library/Frameworks/Python.framework/Versions/3.3/lib/python3.3/site-packages/django/db/backends/__init__.py", line 157, in cursor
    cursor = self.make_debug_cursor(self._cursor())
  File "/Library/Frameworks/Python.framework/Versions/3.3/lib/python3.3/site-packages/django/db/backends/__init__.py", line 129, in _cursor
    self.ensure_connection()
  File "/Library/Frameworks/Python.framework/Versions/3.3/lib/python3.3/site-packages/django/db/backends/__init__.py", line 124, in ensure_connection
    self.connect()
  File "/Library/Frameworks/Python.framework/Versions/3.3/lib/python3.3/site-packages/django/db/utils.py", line 99, in __exit__
    six.reraise(dj_exc_type, dj_exc_value, traceback)
  File "/Library/Frameworks/Python.framework/Versions/3.3/lib/python3.3/site-packages/django/utils/six.py", line 535, in reraise
    raise value.with_traceback(tb)
  File "/Library/Frameworks/Python.framework/Versions/3.3/lib/python3.3/site-packages/django/db/backends/__init__.py", line 124, in ensure_connection
    self.connect()
  File "/Library/Frameworks/Python.framework/Versions/3.3/lib/python3.3/site-packages/django/db/backends/__init__.py", line 112, in connect
    self.connection = self.get_new_connection(conn_params)
  File "/Library/Frameworks/Python.framework/Versions/3.3/lib/python3.3/site-packages/django/db/backends/mysql/base.py", line 435, in get_new_connection
    conn = Database.connect(**conn_params)
  File "/Library/Frameworks/Python.framework/Versions/3.3/lib/python3.3/site-packages/MySQL_python-1.2.3-py3.3-macosx-10.6-intel.egg/MySQLdb/__init__.py", line 81, in Connect
    return Connection(*args, **kwargs)
  File "/Library/Frameworks/Python.framework/Versions/3.3/lib/python3.3/site-packages/MySQL_python-1.2.3-py3.3-macosx-10.6-intel.egg/MySQLdb/connections.py", line 175, in __init__
    super(Connection, self).__init__(*args, **kwargs2)
django.db.utils.OperationalError: (2003, "Can't connect to MySQL server on '127.0.0.1' (61)")
Internal Server Error: /favicon.ico
Traceback (most recent call last):
  File "/Library/Frameworks/Python.framework/Versions/3.3/lib/python3.3/site-packages/django/contrib/sessions/backends/base.py", line 168, in _get_session
    return self._session_cache
AttributeError: 'SessionStore' object has no attribute '_session_cache'

During handling of the above exception, another exception occurred:

Traceback (most recent call last):
  File "/Library/Frameworks/Python.framework/Versions/3.3/lib/python3.3/site-packages/django/db/backends/__init__.py", line 124, in ensure_connection
    self.connect()
  File "/Library/Frameworks/Python.framework/Versions/3.3/lib/python3.3/site-packages/django/db/backends/__init__.py", line 112, in connect
    self.connection = self.get_new_connection(conn_params)
  File "/Library/Frameworks/Python.framework/Versions/3.3/lib/python3.3/site-packages/django/db/backends/mysql/base.py", line 435, in get_new_connection
    conn = Database.connect(**conn_params)
  File "/Library/Frameworks/Python.framework/Versions/3.3/lib/python3.3/site-packages/MySQL_python-1.2.3-py3.3-macosx-10.6-intel.egg/MySQLdb/__init__.py", line 81, in Connect
    return Connection(*args, **kwargs)
  File "/Library/Frameworks/Python.framework/Versions/3.3/lib/python3.3/site-packages/MySQL_python-1.2.3-py3.3-macosx-10.6-intel.egg/MySQLdb/connections.py", line 175, in __init__
    super(Connection, self).__init__(*args, **kwargs2)
_mysql_exceptions.OperationalError: (2003, "Can't connect to MySQL server on '127.0.0.1' (61)")

The above exception was the direct cause of the following exception:

Traceback (most recent call last):
  File "/Library/Frameworks/Python.framework/Versions/3.3/lib/python3.3/site-packages/django/core/handlers/base.py", line 114, in get_response
    response = wrapped_callback(request, *callback_args, **callback_kwargs)
  File "/Library/Frameworks/Python.framework/Versions/3.3/lib/python3.3/site-packages/django/views/generic/base.py", line 69, in view
    return self.dispatch(request, *args, **kwargs)
  File "/Library/Frameworks/Python.framework/Versions/3.3/lib/python3.3/site-packages/django/views/generic/base.py", line 87, in dispatch
    return handler(request, *args, **kwargs)
  File "/Users/never/PycharmProjects/bbs/bbs/views.py", line 12, in get
    if request.user.is_authenticated():
  File "/Library/Frameworks/Python.framework/Versions/3.3/lib/python3.3/site-packages/django/utils/functional.py", line 213, in inner
    self._setup()
  File "/Library/Frameworks/Python.framework/Versions/3.3/lib/python3.3/site-packages/django/utils/functional.py", line 298, in _setup
    self._wrapped = self._setupfunc()
  File "/Library/Frameworks/Python.framework/Versions/3.3/lib/python3.3/site-packages/django/contrib/auth/middleware.py", line 18, in <lambda>
    request.user = SimpleLazyObject(lambda: get_user(request))
  File "/Library/Frameworks/Python.framework/Versions/3.3/lib/python3.3/site-packages/django/contrib/auth/middleware.py", line 10, in get_user
    request._cached_user = auth.get_user(request)
  File "/Library/Frameworks/Python.framework/Versions/3.3/lib/python3.3/site-packages/django/contrib/auth/__init__.py", line 140, in get_user
    user_id = request.session[SESSION_KEY]
  File "/Library/Frameworks/Python.framework/Versions/3.3/lib/python3.3/site-packages/django/contrib/sessions/backends/base.py", line 47, in __getitem__
    return self._session[key]
  File "/Library/Frameworks/Python.framework/Versions/3.3/lib/python3.3/site-packages/django/contrib/sessions/backends/base.py", line 173, in _get_session
    self._session_cache = self.load()
  File "/Library/Frameworks/Python.framework/Versions/3.3/lib/python3.3/site-packages/django/contrib/sessions/backends/db.py", line 20, in load
    expire_date__gt=timezone.now()
  File "/Library/Frameworks/Python.framework/Versions/3.3/lib/python3.3/site-packages/django/db/models/manager.py", line 151, in get
    return self.get_queryset().get(*args, **kwargs)
  File "/Library/Frameworks/Python.framework/Versions/3.3/lib/python3.3/site-packages/django/db/models/query.py", line 301, in get
    num = len(clone)
  File "/Library/Frameworks/Python.framework/Versions/3.3/lib/python3.3/site-packages/django/db/models/query.py", line 77, in __len__
    self._fetch_all()
  File "/Library/Frameworks/Python.framework/Versions/3.3/lib/python3.3/site-packages/django/db/models/query.py", line 854, in _fetch_all
    self._result_cache = list(self.iterator())
  File "/Library/Frameworks/Python.framework/Versions/3.3/lib/python3.3/site-packages/django/db/models/query.py", line 220, in iterator
    for row in compiler.results_iter():
  File "/Library/Frameworks/Python.framework/Versions/3.3/lib/python3.3/site-packages/django/db/models/sql/compiler.py", line 709, in results_iter
    for rows in self.execute_sql(MULTI):
  File "/Library/Frameworks/Python.framework/Versions/3.3/lib/python3.3/site-packages/django/db/models/sql/compiler.py", line 781, in execute_sql
    cursor = self.connection.cursor()
  File "/Library/Frameworks/Python.framework/Versions/3.3/lib/python3.3/site-packages/django/db/backends/__init__.py", line 157, in cursor
    cursor = self.make_debug_cursor(self._cursor())
  File "/Library/Frameworks/Python.framework/Versions/3.3/lib/python3.3/site-packages/django/db/backends/__init__.py", line 129, in _cursor
    self.ensure_connection()
  File "/Library/Frameworks/Python.framework/Versions/3.3/lib/python3.3/site-packages/django/db/backends/__init__.py", line 124, in ensure_connection
    self.connect()
  File "/Library/Frameworks/Python.framework/Versions/3.3/lib/python3.3/site-packages/django/db/utils.py", line 99, in __exit__
    six.reraise(dj_exc_type, dj_exc_value, traceback)
  File "/Library/Frameworks/Python.framework/Versions/3.3/lib/python3.3/site-packages/django/utils/six.py", line 535, in reraise
    raise value.with_traceback(tb)
  File "/Library/Frameworks/Python.framework/Versions/3.3/lib/python3.3/site-packages/django/db/backends/__init__.py", line 124, in ensure_connection
    self.connect()
  File "/Library/Frameworks/Python.framework/Versions/3.3/lib/python3.3/site-packages/django/db/backends/__init__.py", line 112, in connect
    self.connection = self.get_new_connection(conn_params)
  File "/Library/Frameworks/Python.framework/Versions/3.3/lib/python3.3/site-packages/django/db/backends/mysql/base.py", line 435, in get_new_connection
    conn = Database.connect(**conn_params)
  File "/Library/Frameworks/Python.framework/Versions/3.3/lib/python3.3/site-packages/MySQL_python-1.2.3-py3.3-macosx-10.6-intel.egg/MySQLdb/__init__.py", line 81, in Connect
    return Connection(*args, **kwargs)
  File "/Library/Frameworks/Python.framework/Versions/3.3/lib/python3.3/site-packages/MySQL_python-1.2.3-py3.3-macosx-10.6-intel.egg/MySQLdb/connections.py", line 175, in __init__
    super(Connection, self).__init__(*args, **kwargs2)
django.db.utils.OperationalError: (2003, "Can't connect to MySQL server on '127.0.0.1' (61)")
Internal Server Error: /favicon.ico
Traceback (most recent call last):
  File "/Library/Frameworks/Python.framework/Versions/3.3/lib/python3.3/site-packages/django/contrib/sessions/backends/base.py", line 168, in _get_session
    return self._session_cache
AttributeError: 'SessionStore' object has no attribute '_session_cache'

During handling of the above exception, another exception occurred:

Traceback (most recent call last):
  File "/Library/Frameworks/Python.framework/Versions/3.3/lib/python3.3/site-packages/django/db/backends/__init__.py", line 124, in ensure_connection
    self.connect()
  File "/Library/Frameworks/Python.framework/Versions/3.3/lib/python3.3/site-packages/django/db/backends/__init__.py", line 112, in connect
    self.connection = self.get_new_connection(conn_params)
  File "/Library/Frameworks/Python.framework/Versions/3.3/lib/python3.3/site-packages/django/db/backends/mysql/base.py", line 435, in get_new_connection
    conn = Database.connect(**conn_params)
  File "/Library/Frameworks/Python.framework/Versions/3.3/lib/python3.3/site-packages/MySQL_python-1.2.3-py3.3-macosx-10.6-intel.egg/MySQLdb/__init__.py", line 81, in Connect
    return Connection(*args, **kwargs)
  File "/Library/Frameworks/Python.framework/Versions/3.3/lib/python3.3/site-packages/MySQL_python-1.2.3-py3.3-macosx-10.6-intel.egg/MySQLdb/connections.py", line 175, in __init__
    super(Connection, self).__init__(*args, **kwargs2)
_mysql_exceptions.OperationalError: (2003, "Can't connect to MySQL server on '127.0.0.1' (61)")

The above exception was the direct cause of the following exception:

Traceback (most recent call last):
  File "/Library/Frameworks/Python.framework/Versions/3.3/lib/python3.3/site-packages/django/core/handlers/base.py", line 114, in get_response
    response = wrapped_callback(request, *callback_args, **callback_kwargs)
  File "/Library/Frameworks/Python.framework/Versions/3.3/lib/python3.3/site-packages/django/views/generic/base.py", line 69, in view
    return self.dispatch(request, *args, **kwargs)
  File "/Library/Frameworks/Python.framework/Versions/3.3/lib/python3.3/site-packages/django/views/generic/base.py", line 87, in dispatch
    return handler(request, *args, **kwargs)
  File "/Users/never/PycharmProjects/bbs/bbs/views.py", line 12, in get
    if request.user.is_authenticated():
  File "/Library/Frameworks/Python.framework/Versions/3.3/lib/python3.3/site-packages/django/utils/functional.py", line 213, in inner
    self._setup()
  File "/Library/Frameworks/Python.framework/Versions/3.3/lib/python3.3/site-packages/django/utils/functional.py", line 298, in _setup
    self._wrapped = self._setupfunc()
  File "/Library/Frameworks/Python.framework/Versions/3.3/lib/python3.3/site-packages/django/contrib/auth/middleware.py", line 18, in <lambda>
    request.user = SimpleLazyObject(lambda: get_user(request))
  File "/Library/Frameworks/Python.framework/Versions/3.3/lib/python3.3/site-packages/django/contrib/auth/middleware.py", line 10, in get_user
    request._cached_user = auth.get_user(request)
  File "/Library/Frameworks/Python.framework/Versions/3.3/lib/python3.3/site-packages/django/contrib/auth/__init__.py", line 140, in get_user
    user_id = request.session[SESSION_KEY]
  File "/Library/Frameworks/Python.framework/Versions/3.3/lib/python3.3/site-packages/django/contrib/sessions/backends/base.py", line 47, in __getitem__
    return self._session[key]
  File "/Library/Frameworks/Python.framework/Versions/3.3/lib/python3.3/site-packages/django/contrib/sessions/backends/base.py", line 173, in _get_session
    self._session_cache = self.load()
  File "/Library/Frameworks/Python.framework/Versions/3.3/lib/python3.3/site-packages/django/contrib/sessions/backends/db.py", line 20, in load
    expire_date__gt=timezone.now()
  File "/Library/Frameworks/Python.framework/Versions/3.3/lib/python3.3/site-packages/django/db/models/manager.py", line 151, in get
    return self.get_queryset().get(*args, **kwargs)
  File "/Library/Frameworks/Python.framework/Versions/3.3/lib/python3.3/site-packages/django/db/models/query.py", line 301, in get
    num = len(clone)
  File "/Library/Frameworks/Python.framework/Versions/3.3/lib/python3.3/site-packages/django/db/models/query.py", line 77, in __len__
    self._fetch_all()
  File "/Library/Frameworks/Python.framework/Versions/3.3/lib/python3.3/site-packages/django/db/models/query.py", line 854, in _fetch_all
    self._result_cache = list(self.iterator())
  File "/Library/Frameworks/Python.framework/Versions/3.3/lib/python3.3/site-packages/django/db/models/query.py", line 220, in iterator
    for row in compiler.results_iter():
  File "/Library/Frameworks/Python.framework/Versions/3.3/lib/python3.3/site-packages/django/db/models/sql/compiler.py", line 709, in results_iter
    for rows in self.execute_sql(MULTI):
  File "/Library/Frameworks/Python.framework/Versions/3.3/lib/python3.3/site-packages/django/db/models/sql/compiler.py", line 781, in execute_sql
    cursor = self.connection.cursor()
  File "/Library/Frameworks/Python.framework/Versions/3.3/lib/python3.3/site-packages/django/db/backends/__init__.py", line 157, in cursor
    cursor = self.make_debug_cursor(self._cursor())
  File "/Library/Frameworks/Python.framework/Versions/3.3/lib/python3.3/site-packages/django/db/backends/__init__.py", line 129, in _cursor
    self.ensure_connection()
  File "/Library/Frameworks/Python.framework/Versions/3.3/lib/python3.3/site-packages/django/db/backends/__init__.py", line 124, in ensure_connection
    self.connect()
  File "/Library/Frameworks/Python.framework/Versions/3.3/lib/python3.3/site-packages/django/db/utils.py", line 99, in __exit__
    six.reraise(dj_exc_type, dj_exc_value, traceback)
  File "/Library/Frameworks/Python.framework/Versions/3.3/lib/python3.3/site-packages/django/utils/six.py", line 535, in reraise
    raise value.with_traceback(tb)
  File "/Library/Frameworks/Python.framework/Versions/3.3/lib/python3.3/site-packages/django/db/backends/__init__.py", line 124, in ensure_connection
    self.connect()
  File "/Library/Frameworks/Python.framework/Versions/3.3/lib/python3.3/site-packages/django/db/backends/__init__.py", line 112, in connect
    self.connection = self.get_new_connection(conn_params)
  File "/Library/Frameworks/Python.framework/Versions/3.3/lib/python3.3/site-packages/django/db/backends/mysql/base.py", line 435, in get_new_connection
    conn = Database.connect(**conn_params)
  File "/Library/Frameworks/Python.framework/Versions/3.3/lib/python3.3/site-packages/MySQL_python-1.2.3-py3.3-macosx-10.6-intel.egg/MySQLdb/__init__.py", line 81, in Connect
    return Connection(*args, **kwargs)
  File "/Library/Frameworks/Python.framework/Versions/3.3/lib/python3.3/site-packages/MySQL_python-1.2.3-py3.3-macosx-10.6-intel.egg/MySQLdb/connections.py", line 175, in __init__
    super(Connection, self).__init__(*args, **kwargs2)
django.db.utils.OperationalError: (2003, "Can't connect to MySQL server on '127.0.0.1' (61)")
